Workbook

Sheet Sheet4
A1: 事项类型 | B1: (多项)
A2: 所属的ADPM需求 | B2: (多项)
A4: 用人科室 | B4: 求和项:工时（小时） | F4: 用人科室 | G4: 总人天数 | H4: 总人天数 | I4: 应关联ADPM人天数 | J4: 关联ADPM需求工时数量 | K4: 关联ADPM需求人天数量 | L4: 比例
A5: 数据开发部 | B5: 300.75 | F5: 数据测试部 | G5: 278.4499 | H5: 39.87 | I5: =G5/8.5 -> 32.758812 | K5: =J5/8.5 -> 0 | L5: =K5/I5 -> 0
A6: 数据平台部 | B6: 349.1333 | F6: 数据开发部 | G6: 1878.2662 | H6: 410.24 | I6: =G6/8.5 -> 220.97249 | J6: 300.75 | K6: =J6/8.5 -> 35.382353 | L6: =K6/I6 -> 0.16012107
A7: 信息管理部 | B7: 280.5 | F7: 数据平台部 | G7: 1225.3331 | H7: 241.66 | I7: =G7/8.5 -> 144.15684 | J7: 349.1333 | K7: =J7/8.5 -> 41.074506 | L7: =K7/I7 -> 0.2849293
A8: 智能应用二部 | B8: 76.5 | F8: 智能平台部 | G8: 160.6835 | H8: 37 | I8: =G8/8.5 -> 18.903941 | K8: =J8/8.5 -> 0 | L8: =K8/I8 -> 0
A9: 智能应用一部 | B9: 76.5 | F9: 智能应用二部 | G9: 919.4165 | H9: 201.5 | I9: =G9/8.5 -> 108.16665 | J9: 76.5 | K9: =J9/8.5 -> 9 | L9: =K9/I9 -> 0.083204946
A10: 总计 | B10: 1083.3833 | F10: 智能应用一部 | G10: 860.6997 | H10: 141.41 | I10: =G10/8.5 -> 101.25879 | J10: 76.5 | K10: =J10/8.5 -> 9 | L10: =K10/I10 -> 0.088881174

Sheet 数管部工时明细
A1: 工作日期 | B1: 记录名称 | C1: 工时（分钟） | D1: 姓名 | E1: 工号 | F1: 所属科室 | G1: 所属分组 | H1: 是否行员 | I1: 任务描述 | J1: 所属公司 | K1: 开发领域 | L1: 驻场模式 | M1: 所属部落 | N1: 所属小队 | O1: 应用系统 | P1: 批次 | Q1: 所属的ADPM需求 | R1: 工作类型 | S1: 人员等级 | T1: 用户名 | U1: 工号 | V1: 卡片类型 | W1: 人员角色 | X1: ADPM需求类型 | Y1: ADPM需求编号 | Z1: 应用标识 | AA1: 需求牵头部门（三级） | AB1: ADPM需求状态 | AC1: 工作卡状态 | AD1: 描述 | AE1: 工时（小时） | AF1: 需求牵头部门（二级） | AG1: 事项类型 | AH1: 工作大类
A2: 46107 | B2: 指标-工时 | C2: 510 | D2: 邢逸云 | E2: CS9316 | F2: 数据开发部 | H2: 否 | I2: udas_e_gs_corp_dpst_bal_hd开发 | J2: 深圳市长亮科技股份有限公司 | K2: 数据开发 | L2: B模式 | M2: 数据开发部落 | N2: 大数据应用三队 | O2: Hadoop大数据集群 | P2: ADPM需求-X20231222000020[第6批] | Q2: UDAS业务数据模型迁移 | S2: 中级 | T2: cs9316@bosc.cn | U2: cs9316 | V2: 系统功能 | W2: 开发 | X2: 项目 | Y2: X20231222000020 | Z2: BDPHADP | AB2: 进行中 | AC2: 已完成 | AD2: udas_e_gs_corp_dpst_bal_hd新增字段，银联标识、土保标识、源系统期限、源系统期限代码 仓内上下游联调测试（回归部分）按照3轮测试评估 | AE2: 8.5 | AF2: 数据平台部
A3: 46107 | B3: 指标-工时 | C3: 510 | D3: 高源 | E3: 307438 | F3: 智能应用二部 | G3: =VLOOKUP(D3,'人员清单-202603'!D:J,7,FALSE) -> 基础模型组 | H3: 是 | I3: 反诈个人账户风险分模型数据探查 | M3: 智能研发部落 | N3: 基础模型小队 | T3: 307438@bosc.cn | U3: 307438 | V3: 事项任务 | AC3: 进行中 | AE3: 8.5 | AG3: 开发（含模型、应用、数仓等）
A4: 46107 | B4: 指标-工时 | C4: 510 | D4: 包惠 | E4: CS5698 | F4: 数据开发部 | H4: 否 | I4: MRP迁移 | J4: 深圳市长亮科技股份有限公司 | K4: 数据开发 | L4: B模式 | M4: 数据开发部落 | N4: 基础数据小队 | O4: Hadoop大数据集群 | Q4: 基于整合模型金融市场领域的MRP迁移改造需求 | S4: 中级 | T4: cs5698@bosc.cn | U4: cs5698 | V4: 系统功能 | W4: 开发 | X4: 维护需求 | Y4: X20260224000012 | Z4: BDPHADP | AB4: 进行中 | AC4: 详细设计 | AE4: 8.5 | AF4: 数据开发部
A5: 46107 | B5: 指标-工时 | C5: 660 | D5: 张典兵 | E5: CS2303 | F5: 数据平台部 | H5: 否 | I5: 公司客户关系管理开发-CCRM-X20250409000030 | J5: 高伟达软件股份有限公司 | K5: CRM | L5: B模式 | M5: 信息管理部落 | N5: 同业CRM小队 | O5: 公司客户关系管理 | P5: ADPM需求-X20250409000030[第1批] | Q5: 投行业务管理平台优化需求 | S5: 资深 | T5: cs2303@bosc.cn | U5: cs2303 | V5: 系统功能 | W5: 管理人员（小队级） | X5: 项目 | Y5: X20250409000030 | Z5: CCRM | AA5: 开发一部 | AB5: 进行中 | AC5: 已完成 | AD5: 1. 代码开发 2. 配合联调 | AE5: 11 | AF5: 上海开发测试中心
A6: 46107 | B6: 指标-工时 | C6: 510 | D6: 陈烨 | E6: CS6318 | F6: 数据平台部 | H6: 否 | I6: 对公CRM移动端-新增周报管理功能-需求和系统分析 | J6: 北京东方国信科技股份有限公司 | K6: CRM | L6: B模式 | M6: 信息管理部落 | N6: 零售对公CRM APP小队 | O6: 公司客户关系管理 | Q6: 关于在对公CRM新增周报管理功能的需求 | S6: 中级 | T6: cs6318@bosc.cn | U6: cs6318 | V6: 系统功能 | W6: 开发 | X6: 维护需求 | Y6: X20260228000040 | Z6: CCRM | AB6: 进行中 | AC6: 详细设计 | AE6: 8.5 | AF6: 数据平台部
A7: 46107 | B7: 指标-工时 | C7: 510 | D7: 雷露 | E7: CS7825 | F7: 数据开发部 | H7: 否 | I7: X20250612000039_模型新增互联网标签 | J7: 深圳市长亮科技股份有限公司 | K7: 数据开发 | L7: B模式 | M7: 数据开发部落 | N7: 大数据应用三队 | O7: Hadoop大数据集群 | P7: ADPM需求-X20250612000039[第6批] | Q7: 2025年经营指标体系建设 | S7: 中级 | T7: cs7825@bosc.cn | U7: cs7825 | V7: 系统功能 | W7: 开发 | X7: 项目 | Y7: X20250612000039 | Z7: BDPHADP | AB7: 进行中 | AC7: 已完成 | AD7: UDAS_F_GS_IND_FIN_LOAN_DTL_N新增互联网标签 脚本开发 UDAS_F_GS_IND_FIN_LOAN_DTL_N新增互联网标签 单元测试 | AE7: 8.5 | AF7: 综合管理部
A8: 46107 | B8: 指标-工时 | C8: 510 | D8: 吕恩元 | E8: CS0966 | F8: 数据开发部 | H8: 否 | I8: KPI项目-KPI页面配置调整及数据验证 | J8: 北京宇信科技集团股份有限公司 | K8: 数据开发 | L8: B模式 | M8: 信息管理部落 | N8: UDAS风险数据小队 | O8: 掌上行 | P8: ADPM需求-X20250612000039[第6批] | Q8: 2025年经营指标体系建设 | S8: 高级 | T8: cs0966@bosc.cn | U8: cs0966 | V8: 系统功能 | W8: 需求分析BA | X8: 项目 | Y8: X20250612000039 | Z8: AMBI | AB8: 进行中 | AC8: 已完成 | AD8: 机构KPI页面配置及数据测试验证 | AE8: 8.5 | AF8: 综合管理部
A9: 46107 | B9: 指标-工时 | C9: 510 | D9: 陈旭东 | E9: CS1663 | F9: 数据开发部 | H9: 否 | I9: 视图底表构建-天正 | J9: 上海天正智能数据服务有限公司 | K9: 数据开发 | L9: B模式 | M9: 信息管理部落 | N9: NRP集市小队 | O9: Hadoop大数据集群 | P9: ADPM需求-X20240926000006[第3批] | Q9: 2024年度经营单位数字化管理建设项目 | S9: 高级 | T9: cs1663@bosc.cn | U9: cs1663 | V9: 系统功能 | W9: 开发 | X9: 项目 | Y9: X20240926000006 | Z9: BDPHADP | AB9: 进行中 | AC9: 已完成 | AD9: RDI_F_IND_AGNFUND_TX_BW作业迁移分析，S层缺失字段登记、脚本开发 | AE9: 8.5 | AF9: 信息管理部
A10: 46107 | B10: 指标-工时 | C10: 600 | D10: 胡丽 | E10: CS7763 | F10: 数据测试部 | H10: 否 | I10: X20240108000018__慧信工程-监管报送集市建设_第8批次 | J10: 中电金信软件有限公司 | L10: A模式 | M10: 核心系统重构项目组 | N10: 数据小队 | P10: ADPM需求-X20240108000018[第8批] | Q10: 慧信工程-监管报送集市建设 | S10: 高级 | T10: cs7763@bosc.cn | U10: cs7763 | V10: 条目需求 | W10: 测试 | X10: 项目 | Y10: X20240108000018 | AB10: 进行中 | AC10: 可行性分析 | AE10: 10 | AF10: 数据开发部
A11: 46107 | B11: 指标-工时 | C11: 510 | D11: 秦连奥 | E11: CS101076 | F11: 数据平台部 | H11: 否 | I11: MMM日常维护4 | J11: 深圳市长亮科技股份有限公司 | K11: 数据开发 | L11: B模式 | O11: 信用风险监测预警 | S11: 中级 | T11: cs101076@bosc.cn | U11: cs101076 | V11: 系统功能 | W11: 开发 | Z11: RAD | AC11: 详细设计 | AD11: 1.查看调试客户视图，集团视图代码逻辑。 | AE11: 8.5
A12: 46107 | B12: 指标-工时 | C12: 510 | D12: 胡文彬 | E12: CS100924 | F12: 数据测试部 | H12: 否 | I12: X20240108000018__慧信工程-监管报送集市建设_第8批次 | J12: 上海复深蓝软件股份有限公司 | L12: A模式 | M12: 数据开发部落 | N12: 数据测试小队 | P12: ADPM需求-X20240108000018[第8批] | Q12: 慧信工程-监管报送集市建设 | S12: 中级 | T12: cs100924@bosc.cn | U12: cs100924 | V12: 条目需求 | X12: 项目 | Y12: X20240108000018 | AB12: 进行中 | AC12: 可行性分析 | AE12: 8.5 | AF12: 数据开发部
A13: 46107 | B13: 指标-工时 | C13: 690 | D13: 任凯 | E13: CS101133 | F13: 数据开发部 | H13: 否 | I13: 一表通配合测试 | J13: 南京科融数据系统股份有限公司 | K13: 监管报送 | L13: B模式 | M13: 监管报送部落 | N13: 银保监报送小队 | O13: 监管可信区 | P13: ADPM需求-X20240108000018[第8批] | Q13: 慧信工程-监管报送集市建设 | S13: 中级 | T13: cs101133@bosc.cn | U13: cs101133 | V13: 系统功能 | W13: 开发 | X13: 项目 | Y13: X20240108000018 | Z13: RTZ | AB13: 进行中 | AC13: 详细设计 | AD13: 重点指标配合测试、新旧线比对配合测试 | AE13: 11.5 | AF13: 数据开发部
A14: 46107 | B14: 指标-工时 | C14: 510 | D14: 单丽可 | E14: CS3225 | F14: 数据开发部 | H14: 否 | I14: 客户经理业绩功能-CRM集市开发 | J14: 上海天正智能数据服务有限公司 | K14: 数据开发 | L14: B模式 | M14: 数据开发部落 | N14: 大数据应用一队 | O14: Hadoop大数据集群 | P14: ADPM需求-X20251104000031[第1批] | Q14: 关于对公CRM客户经理业绩前端页面调整的需求书 | S14: 中级 | T14: cs3225@bosc.cn | U14: cs3225 | V14: 系统功能 | W14: 开发 | X14: 维护需求 | Y14: X20251104000031 | Z14: BDPHADP | AB14: 进行中 | AC14: 已完成 | AD14: 新增作业:E_CRM_C_MNGR_WORK_STC_SUM(对公客户经理工作结构统计表) 初始化和批量脚本开发完成 | AE14: 8.5 | AF14: 数据平台部
A15: 46107 | B15: 指标-工时 | C15: 510 | D15: 徐宥 | E15: CS4237 | F15: 数据测试部 | H15: 否 | I15: X20240108000018__慧信工程-监管报送集市建设_第8批次 | J15: 高伟达软件股份有限公司 | L15: A模式 | M15: 上海科技管理部落 | N15: 配置管理小队（上海） | P15: ADPM需求-X20240108000018[第8批] | Q15: 慧信工程-监管报送集市建设 | S15: 初级 | T15: cs4237@bosc.cn | U15: cs4237 | V15: 条目需求 | W15: 配置管理员 | X15: 项目 | Y15: X20240108000018 | AB15: 进行中 | AC15: 可行性分析 | AE15: 8.5 | AF15: 数据开发部
A16: 46107 | B16: 指标-工时 | C16: 610 | D16: 梁天蕾 | E16: CS1711 | F16: 数据平台部 | H16: 否 | I16: 公司客户关系管理开发-CCRM-X20250409000030 | J16: 高伟达软件股份有限公司 | K16: CRM | L16: B模式 | M16: 信息管理部落 | N16: 零售对公CRM APP小队 | O16: 公司客户关系管理 | P16: ADPM需求-X20250409000030[第1批] | Q16: 投行业务管理平台优化需求 | S16: 中级 | T16: cs1711@bosc.cn | U16: cs1711 | V16: 系统功能 | W16: 开发 | X16: 项目 | Y16: X20250409000030 | Z16: CCRM | AA16: 开发一部 | AB16: 进行中 | AC16: 已完成 | AD16: 接口开发 | AE16: 10.1667 | AF16: 上海开发测试中心
A17: 46107 | B17: 指标-工时 | C17: 510 | D17: 姚彬晖 | E17: CS100416 | F17: 数据开发部 | H17: 否 | I17: X20250305000005-BDPHADP | J17: 北京宇信科技集团股份有限公司 | K17: 数据开发 | L17: B模式 | M17: 监管报送部落 | N17: 监管报送集市小队 | O17: Hadoop大数据集群 | P17: ADPM需求-X20250305000005[第1批] | Q17: 关于江苏金租接入车生态项目的需求书 | S17: 中级 | T17: cs100416@bosc.cn | U17: cs100416 | V17: 系统功能 | W17: 开发 | X17: 年度预算制 | Y17: X20250305000005 | Z17: BDPHADP | AA17: 开发一部 | AB17: 进行中 | AC17: 已完成 | AD17: 1.X20250305000005-江苏金租接入车生态需求:在测试环境跑一表通报表20260313的数据，并配合下游进行测试验证。 2.X20250305000005-江苏金租接入车生态需求:在自动化测试平台测试20260327版本的脚本。 3.现金报送需求：配合下游排查集市“核心收费交易明细”表20251231期“科目代码”、“账号”字段的生产数据问题。 | AE17: 8.5 | AF17: 上海开发测试中心
A18: 46107 | B18: 指标-工时 | C18: 510 | D18: 吴杰 | E18: CS6140 | F18: 信息管理部 | H18: 否 | I18: KPI项目-非标准化下钻页面-UDAS数据开发 | J18: 北京宇信科技集团股份有限公司 | K18: 数据开发 | L18: B模式 | M18: 信息管理部落 | N18: NRP集市小队 | O18: 统一报表及指标平台 | P18: ADPM需求-X20250612000039[第6批] | Q18: 2025年经营指标体系建设 | S18: 高级 | T18: cs6140@bosc.cn | U18: cs6140 | V18: 系统功能 | W18: 开发 | X18: 项目 | Y18: X20250612000039 | Z18: UDAS | AB18: 进行中 | AC18: 已完成 | AD18: 新兴板块-下钻页面指标、管理指标:修改一个存储过程【分行代客客户模型黄金租赁有效户逻辑修改】 | AE18: 8.5 | AF18: 综合管理部
A19: 46107 | B19: 指标-工时 | C19: 510 | D19: 曹婷 | E19: CS100315 | F19: 数据开发部 | H19: 否 | I19: CAFBDM开发任务 | J19: 天阳宏业科技股份有限公司 | K19: 数据开发 | L19: B模式 | M19: 数据开发部落 | N19: 基础数据小队 | O19: 金融基础数据模型计算区 | P19: ADPM需求-X20260204000040[第2批] | Q19: 【反电诈】关于优化警银数据交互功能的需求 | S19: 中级 | T19: cs100315@bosc.cn | U19: cs100315 | V19: 系统功能 | X19: 维护需求 | Y19: X20260204000040 | Z19: CAFBDM | AA19: 基础中台开发团队 | AB19: 进行中 | AC19: 已完成 | AE19: 8.5 | AF19: 苏州开发测试中心
A20: 46107 | B20: 指标-工时 | C20: 510 | D20: 余晶鑫 | E20: CS9091 | F20: 数据开发部 | H20: 否 | I20: 监管可信区-银丰 | J20: 北京银丰新融科技开发有限公司 | K20: 监管报送 | L20: B模式 | M20: 监管报送部落 | N20: 银保监报送小队 | O20: 监管可信区 | P20: ADPM需求-X20250620000012[第1批] | Q20: 监管一表通三期 | S20: 中级 | T20: cs9091@bosc.cn | U20: cs9091 | V20: 系统功能 | X20: 项目 | Y20: X20250620000012 | Z20: RTZ | AB20: 进行中 | AC20: 已完成 | AE20: 8.5 | AF20: 数据开发部
A21: 46107 | B21: 指标-工时 | C21: 510 | D21: 陈粉玲 | E21: CS6565 | F21: 信息管理部 | H21: 否 | I21: 帆软看板开发---蔡、陈 | J21: 上海天正智能数据服务有限公司 | K21: 数据开发 | L21: B模式 | O21: 司库应用计算区 | P21: ADPM需求-X20240423000001[第12批] | Q21: 关于司库进阶版功能建设的需求 | S21: 中级 | T21: cs6565@bosc.cn | U21: cs6565 | V21: 系统功能 | W21: 数据分析助理 | X21: 项目 | Y21: X20240423000001 | Z21: M.TBS.TCA | AA21: 司库开发团队 | AB21: 进行中 | AC21: 已完成 | AD21: 司库数据集团资金日报明细表数据核对 | AE21: 8.5 | AF21: 上海开发测试中心
A22: 46107 | B22: 指标-工时 | C22: 510 | D22: 童加明 | E22: CS6758 | F22: 数据测试部 | H22: 否 | I22: 风险模块功能优化 | J22: 神州数码融信软件有限公司 | L22: A模式 | M22: 数据开发部落 | N22: 数据测试小队 | O22: 司库风险管理 | P22: ADPM需求-X20240423000001[第12批] | Q22: 关于司库进阶版功能建设的需求 | S22: 中级 | T22: cs6758@bosc.cn | U22: cs6758 | V22: 系统功能 | X22: 项目 | Y22: X20240423000001 | Z22: M.TBS.RM | AA22: 司库开发团队 | AB22: 进行中 | AC22: 已完成 | AE22: 8.5 | AF22: 上海开发测试中心
A23: 46107 | B23: 指标-工时 | C23: 255 | D23: 桑双双 | E23: CS9009 | F23: 数据开发部 | H23: 否 | I23: X20260106000017-BDPHADP | J23: 天阳宏业科技股份有限公司 | K23: 数据开发 | L23: B模式 | M23: 数据开发部落 | N23: 大数据应用二队 | O23: Hadoop大数据集群 | P23: ADPM需求-X20260106000017[第1批] | Q23: IRMS票易贷数据迁移功能优化业务需求书-业务功能类V4.5 | S23: 中级 | T23: cs9009@bosc.cn | U23: cs9009 | V23: 系统功能 | W23: 开发 | X23: 年度预算制 | Y23: X20260106000017 | Z23: BDPHADP | AA23: 开发一部 | AB23: 进行中 | AC23: 详细设计 | AD23: 票易贷测试 | AE23: 4.25 | AF23: 上海开发测试中心
A24: 46107 | B24: 指标-工时 | C24: 556 | D24: 吴梦飞 | E24: CS9665 | F24: 数据开发部 | H24: 否 | I24: 一表通配合测试 | J24: 南京科融数据系统股份有限公司 | K24: 监管报送 | L24: B模式 | M24: 监管报送部落 | N24: 银保监报送小队 | O24: 监管可信区 | P24: ADPM需求-X20240108000018[第8批] | Q24: 慧信工程-监管报送集市建设 | S24: 中级 | T24: cs9665@bosc.cn | U24: cs9665 | V24: 系统功能 | X24: 项目 | Y24: X20240108000018 | Z24: RTZ | AB24: 进行中 | AC24: 详细设计 | AD24: 一表通旧线数据与新线数据对比，并分析差异原因 重点指标差异对比 | AE24: 9.2667 | AF24: 数据开发部
A25: 46107 | B25: 指标-工时 | C25: 510 | D25: 王楚齐 | E25: CS8932 | F25: 数据开发部 | H25: 否 | I25: X20240119000030-大数据仓库及应用系统数据时效治理专项优化项目(2024年)-第2批次 | J25: 深圳市长亮科技股份有限公司 | K25: 数据开发 | L25: B模式 | M25: 数据开发部落 | N25: 基础数据小队 | P25: ADPM需求-X20240119000030[第2批] | Q25: 大数据仓库及应用系统数据时效治理专项优化项目(2024年) | S25: 中级 | T25: cs8932@bosc.cn | U25: cs8932 | V25: 条目需求 | W25: 开发 | X25: 项目 | Y25: X20240119000030 | AB25: 进行中 | AC25: 待测试 | AD25: RLG_CHAIN_CCM_COMPANY_ADS 配合CCM迁移切换 | AE25: 8.5 | AF25: 数据开发部
A26: 46107 | B26: 指标-工时 | C26: 550 | D26: 李宇 | E26: CS101206 | F26: 数据开发部 | H26: 否 | I26: 一表通配合测试 | J26: 南京科融数据系统股份有限公司 | K26: 监管报送 | L26: B模式 | M26: 监管报送部落 | N26: 银保监报送小队 | O26: 监管可信区 | P26: ADPM需求-X20240108000018[第8批] | Q26: 慧信工程-监管报送集市建设 | S26: 中级 | T26: cs101206@bosc.cn | U26: cs101206 | V26: 系统功能 | X26: 项目 | Y26: X20240108000018 | Z26: RTZ | AB26: 进行中 | AC26: 详细设计 | AD26: 1.验证重点指标修复后问题 2.开发一表通转east对公信贷分户账逻辑 | AE26: 9.1667 | AF26: 数据开发部
A27: 46107 | B27: 指标-工时 | C27: 510 | D27: 桂贝 | E27: CS0493 | F27: 数据开发部 | H27: 否 | I27: CAFBDM开发 | J27: 上海天正智能数据服务有限公司 | K27: 数据开发 | L27: B模式 | M27: 数据开发部落 | N27: 基础数据小队 | O27: 金融基础数据模型计算区 | P27: ADPM需求-X20251210000003[第2批] | Q27: 运营风险监控平台存量模型优化（重要物品类、账户及交易类等） | S27: 高级 | T27: cs0493@bosc.cn | U27: cs0493 | V27: 系统功能 | W27: 开发 | X27: 维护需求 | Y27: X20251210000003 | Z27: CAFBDM | AA27: 智能创新开发团队 | AB27: 进行中 | AC27: 已完成 | AD27: 整合模型损益开发测试 | AE27: 8.5 | AF27: 苏州开发测试中心
A28: 46107 | B28: 指标-工时 | C28: 255 | D28: 桑双双 | E28: CS9009 | F28: 数据开发部 | H28: 否 | I28: 【数据仓库集群】数据仓库集群配合优化 | J28: 天阳宏业科技股份有限公司 | K28: 数据开发 | L28: B模式 | M28: 数据开发部落 | N28: 大数据应用二队 | O28: Hadoop大数据集群 | P28: ADPM需求-X20250422000007[第2批] | Q28: 零售内评分池对接、中小企业营收取数逻辑优化的运维需求 | S28: 中级 | T28: cs9009@bosc.cn | U28: cs9009 | V28: 系统功能 | W28: 开发 | X28: 维护需求 | Y28: X20250422000007 | Z28: BDPHADP | AA28: 开发七部 | AB28: 进行中 | AC28: 已完成 | AD28: 写白皮书 E_FRM_NRWA_RETAIL_EXPOSURE_2 E_FRM_I9_DEVAL_CRDCARD_MT 写需求概要设计 | AE28: 4.25 | AF28: 上海开发测试中心
A29: 46107 | B29: 指标-工时 | C29: 510 | D29: 周井茹 | E29: CS7628 | F29: 数据开发部 | H29: 否 | I29: MRP开发 | J29: 深圳市长亮科技股份有限公司 | K29: 数据开发 | L29: B模式 | M29: 数据开发部落 | N29: 基础数据小队 | O29: Hadoop大数据集群 | P29: ADPM需求-X20251219000038[第2批] | Q29: udas和数仓对上海地区支行代客业务指标统计适配性改造 | S29: 中级 | T29: cs7628@bosc.cn | U29: cs7628 | V29: 系统功能 | W29: 开发 | X29: 维护需求 | Y29: X20251219000038 | Z29: BDPHADP | AB29: 进行中 | AC29: 已完成 | AD29: 债券积数表查数 中收表测试、低成本负债测试 | AE29: 8.5 | AF29: 数据开发部
A30: 46107 | B30: 指标-工时 | C30: 525 | D30: 刘洲 | E30: CS100308 | F30: 数据测试部 | H30: 否 | I30: X20240108000018__慧信工程-监管报送集市建设_第8批次 | J30: 京北方信息技术股份有限公司 | L30: A模式 | P30: ADPM需求-X20240108000018[第8批] | Q30: 慧信工程-监管报送集市建设 | S30: 中级 | T30: cs100308@bosc.cn | U30: cs100308 | V30: 条目需求 | X30: 项目 | Y30: X20240108000018 | AB30: 进行中 | AC30: 可行性分析 | AE30: 8.75 | AF30: 数据开发部
A31: 46107 | B31: 指标-工时 | C31: 510 | D31: 王娟 | E31: CS0987 | F31: 数据开发部 | H31: 否 | I31: 网点交易需求-掌上行开发 | J31: 北京宇信科技集团股份有限公司 | K31: 数据开发 | L31: B模式 | O31: 掌上行 | P31: ADPM需求-X20250708000021[第2批] | Q31: 网点交易量等指标掌上行展示工作 | S31: 中级 | T31: cs0987@bosc.cn | U31: cs0987 | V31: 系统功能 | W31: 需求分析BA | X31: 维护需求 | Y31: X20250708000021 | Z31: AMBI | AB31: 进行中 | AC31: 已完成 | AE31: 8.5 | AF31: 数据开发部
A32: 46107 | B32: 指标-工时 | C32: 525 | D32: 尚佳宝 | E32: CS100902 | F32: 数据测试部 | H32: 否 | I32: X20240108000018__慧信工程-监管报送集市建设_第8批次 | J32: 上海复深蓝软件股份有限公司 | L32: A模式 | M32: 数据开发部落 | N32: 数据测试小队 | P32: ADPM需求-X20240108000018[第8批] | Q32: 慧信工程-监管报送集市建设 | S32: 中级 | T32: cs100902@bosc.cn | U32: cs100902 | V32: 条目需求 | X32: 项目 | Y32: X20240108000018 | AB32: 进行中 | AC32: 可行性分析 | AE32: 8.75 | AF32: 数据开发部
A33: 46107 | B33: 指标-工时 | C33: 510 | D33: 符伟 | E33: CS0574 | F33: 数据开发部 | H33: 否 | I33: X20251027000041-BDPDWS | J33: 北京宇信科技集团股份有限公司 | K33: 数据开发 | L33: B模式 | M33: 信息管理部落 | N33: NRP集市小队 | O33: DWS数据集群 | P33: ADPM需求-X20251027000041[第1批] | Q33: 南通众和应收账款业务业务需求书 | S33: 中级 | T33: cs0574@bosc.cn | U33: cs0574 | V33: 系统功能 | W33: 开发 | X33: 年度预算制 | Y33: X20251027000041 | Z33: BDPDWS | AA33: 开发一部 | AB33: 进行中 | AC33: 已完成 | AD33: UDAS_F_CORP_LOAN_BAL_MESSAGE\UDAS_F_CORP_CONSLOAN_BAL\UDAS_F_CORP_LOAN_OCCUR_MESSAGE\UDAS_F_CORP_LOAN_INFO 测试验证。 | AE33: 8.5 | AF33: 上海开发测试中心
A34: 46107 | B34: 指标-工时 | C34: 510 | D34: 李梁 | E34: CS100191 | F34: 数据测试部 | H34: 否 | I34: X20240108000018__慧信工程-监管报送集市建设_第8批次 | J34: 中电金信软件有限公司 | L34: A模式 | M34: 数据开发部落 | N34: 数据测试小队 | P34: ADPM需求-X20240108000018[第8批] | Q34: 慧信工程-监管报送集市建设 | S34: 高级 | T34: cs100191@bosc.cn | U34: cs100191 | V34: 条目需求 | X34: 项目 | Y34: X20240108000018 | AB34: 进行中 | AC34: 可行性分析 | AD34: 503518 | AE34: 8.5 | AF34: 数据开发部
A35: 46107 | B35: 指标-工时 | C35: 510 | D35: 孙建国 | E35: CS0375 | F35: 数据平台部 | H35: 否 | I35: UDAS对公模型优化整合分析 | J35: 北京宇信科技集团股份有限公司 | K35: 数据开发 | L35: B模式 | M35: 信息管理部落 | N35: UDAS公共1队 | O35: 掌上行 | P35: ADPM需求-X20231222000020[第6批] | Q35: UDAS业务数据模型迁移 | S35: 中级 | T35: cs0375@bosc.cn | U35: cs0375 | V35: 系统功能 | W35: 开发 | X35: 项目 | Y35: X20231222000020 | Z35: AMBI | AB35: 进行中 | AC35: 已完成 | AD35: 掌上行 20260327版本 在 PI 环境部署测试验证 ； 已完成 100% ； | AE35: 8.5 | AF35: 数据平台部
A36: 46106.964 | B36: 指标-工时 | C36: 510 | D36: 曹树森 | E36: CS8393 | F36: 数据开发部 | H36: 否 | I36: MRP迁移 | J36: 深圳市长亮科技股份有限公司 | K36: 数据开发 | L36: B模式 | M36: 数据开发部落 | N36: 基础数据小队 | O36: Hadoop大数据集群 | Q36: 基于整合模型金融市场领域的MRP迁移改造需求 | S36: 中级 | T36: cs8393@bosc.cn | U36: cs8393 | V36: 系统功能 | W36: 开发 | X36: 维护需求 | Y36: X20260224000012 | Z36: BDPHADP | AB36: 进行中 | AC36: 详细设计 | AD36: 脚本开发开发中1个：企业信用受益权投资流水表，增加补录数据组逻辑，脚本开发自测 | AE36: 8.5 | AF36: 数据开发部
A37: 46106.917 | B37: 指标-工时 | C37: 510 | D37: 胡艳红 | E37: CS7862 | F37: 数据开发部 | H37: 否 | I37: 数仓模型设计--李、胡 | J37: 上海天正智能数据服务有限公司 | K37: 数据开发 | L37: B模式 | M37: 数据开发部落 | N37: 基础数据小队 | O37: 司库应用计算区 | P37: ADPM需求-X20240423000001[第12批] | Q37: 关于司库进阶版功能建设的需求 | S37: 中级 | T37: cs7862@bosc.cn | U37: cs7862 | V37: 系统功能 | W37: 开发 | X37: 项目 | Y37: X20240423000001 | Z37: M.TBS.TCA | AA37: 司库开发团队 | AB37: 进行中 | AC37: 已完成 | AD37: 联调 接口监管报送17接口（应收款项）、监管报送18接口（应付款项），监管报送04接口（债券），监管报送03接口（银行贷款） | AE37: 8.5 | AF37: 上海开发测试中心
A38: 46106.904 | B38: 指标-工时 | C38: 750 | D38: 郑于东 | E38: CS101220 | F38: 信息管理部 | H38: 否 | I38: 产品设计--崔 | J38: 北京宇信科技集团股份有限公司 | K38: 数据开发 | L38: B模式 | M38: 信息管理部落 | N38: UDAS公共1队 | O38: 司库应用计算区 | P38: ADPM需求-X20240423000001[第12批] | Q38: 关于司库进阶版功能建设的需求 | S38: 中级 | T38: cs101220@bosc.cn | U38: cs101220 | V38: 系统功能 | X38: 项目 | Y38: X20240423000001 | Z38: M.TBS.TCA | AA38: 司库开发团队 | AB38: 进行中 | AC38: 已完成 | AD38: 开发宝山国资委-债务融资驾驶舱 和应收应付驾驶舱 | AE38: 12.5 | AF38: 上海开发测试中心
A39: 46106.893 | B39: 指标-工时 | C39: 310 | D39: 扶子懿 | E39: CS100010 | F39: 数据开发部 | H39: 否 | I39: 整合模型追数 | J39: 神州数码融信软件有限公司 | K39: 数据开发 | L39: B模式 | M39: 数据开发部落 | N39: 基础数据小队 | O39: 金融基础数据模型计算区 | Q39: 电信网络诈骗受害人保护项目业务需求书 | S39: 中级 | T39: cs100010@bosc.cn | U39: cs100010 | V39: 系统功能 | W39: 开发 | X39: 项目 | Y39: X20250117000017 | Z39: CAFBDM | AA39: 基础中台开发团队 | AB39: 进行中 | AC39: 详细设计 | AD39: SQLREVIEW生产数据验证。 | AE39: 5.1667 | AF39: 苏州开发测试中心
A40: 46106.86 | B40: 指标-工时 | C40: 85 | D40: 王正超 | E40: 303471 | F40: 数据平台部 | G40: =VLOOKUP(D40,'人员清单-202603'!D:J,7,FALSE) -> 应用开发组 | H40: 是 | I40: crm开发进度对齐会 | M40: 信息管理部落 | N40: 零售对公CRM APP小队 | T40: 303471@bosc.cn | U40: 303471 | V40: 事项任务 | W40: 小队长 | AC40: 进行中 | AE40: 1.4167 | AG40: 项目管理（含外包管理）
...

Sheet 人员清单-202603
A1: 实际内设部 | B1: EHR内设部 | C1: 内设部是否变动 | D1: 姓名 | E1: 工号 | F1: 现岗位 | G1: 拟岗位 | H1: 岗位是否变动 | I1: 现角色标签 （组长/骨干） | J1: 拟分组
A2: 信息管理部 | B2: 信息管理部 | C2: 0 | D2: 舒宝龙 | E2: 305069 | F2: 数据分析 | G2: 数据分析 | H2: 0 | I2: 组长 | J2: 负责人 | K2: =C2+H2 -> 0
A3: 信息管理部 | B3: 信息管理部 | C3: 0 | D3: 任若琳 | E3: 307309 | F3: 数据分析 | G3: 需求分析 | H3: 1 | J3: 服务管理组 | K3: =C3+H3 -> 1
A4: 信息管理部 | B4: 信息管理部 | C4: 0 | D4: 成绘茜 | E4: 307444 | F4: 数据分析 | G4: 需求分析 | H4: 1 | J4: 服务管理组 | K4: =C4+H4 -> 1
A5: 信息管理部 | B5: 信息管理部 | C5: 0 | D5: 陆应佳玥 | E5: 305199 | F5: 数据分析 | G5: 需求分析 | H5: 1 | J5: 服务管理组 | K5: =C5+H5 -> 1
A6: 信息管理部 | B6: 信息管理部 | C6: 0 | D6: 李小萌 | E6: 306533 | F6: 数据分析 | G6: 需求分析 | H6: 1 | J6: 服务管理组 | K6: =C6+H6 -> 1
A7: 信息管理部 | B7: 信息管理部 | C7: 0 | D7: 宋轲 | E7: 307028 | F7: 数据分析 | G7: 数据分析 | H7: 0 | J7: 服务支持组 | K7: =C7+H7 -> 0
A8: 信息管理部 | B8: 信息管理部 | C8: 0 | D8: 张文婉 | E8: 304804 | F8: 数据分析 | G8: 数据分析 | H8: 0 | J8: 服务支持组 | K8: =C8+H8 -> 0
A9: 信息管理部 | B9: 信息管理部 | C9: 0 | D9: 刘雅雯 | E9: 307443 | F9: 数据分析 | G9: 数据分析 | H9: 0 | J9: 服务支持组 | K9: =C9+H9 -> 0
A10: 信息管理部 | B10: 信息管理部 | C10: 0 | D10: 孙菡悦 | E10: 305446 | F10: 数据分析 | G10: 数据分析 | H10: 0 | J10: 服务支持组 | K10: =C10+H10 -> 0
A11: 信息管理部 | B11: 信息管理部 | C11: 0 | D11: 刘思言 | E11: 305409 | F11: 数据分析 | G11: 数据分析 | H11: 0 | J11: 服务支持组 | K11: =C11+H11 -> 0
A12: 信息管理部 | B12: 信息管理部 | C12: 0 | D12: 谢丹伶 | E12: 305588 | F12: 数据分析 | G12: 数据分析 | H12: 0 | J12: 服务支持组 | K12: =C12+H12 -> 0
A13: 数据测试部 | B13: 综合管理部 | C13: 1 | D13: 杨萍 | E13: 306253 | F13: 数据测试 | G13: 负责人 | H13: 1 | I13: 组长 | J13: 负责人 | K13: =C13+H13 -> 2
A14: 数据测试部 | B14: 综合管理部 | C14: 1 | D14: 马亦沁 | E14: 305419 | F14: 数据测试 | G14: 数据测试 | H14: 0 | J14: 测试管理组 | K14: =C14+H14 -> 1
A15: 数据测试部 | B15: 综合管理部 | C15: 1 | D15: 蒋书润 | E15: 306762 | F15: 数据测试 | G15: 数据测试 | H15: 0 | J15: 测试管理组 | K15: =C15+H15 -> 1
A16: 数据测试部 | B16: 综合管理部 | C16: 1 | D16: 陈世辉 | E16: 306537 | F16: 数据测试 | G16: 数据测试 | H16: 0 | I16: 骨干 | J16: 测试管理组 | K16: =C16+H16 -> 1
A17: 数据测试部 | B17: 综合管理部 | C17: 1 | D17: 曹翔 | E17: 306530 | F17: 数据测试 | G17: 数据测试 | H17: 0 | J17: 测试管理组 | K17: =C17+H17 -> 1
A18: 数据开发部 | B18: 数据开发部 | C18: 0 | D18: 顾恺 | E18: 319914 | F18: 负责人 | G18: 负责人 | H18: 0 | J18: 负责人 | K18: =C18+H18 -> 0
A19: 数据开发部 | B19: 数据开发部 | C19: 0 | D19: 杨青 | E19: 302330 | F19: 数据研发 | G19: 架构管理 | H19: 1 | J19: 协管 | K19: =C19+H19 -> 1
A20: 数据开发部 | B20: 数据开发部 | C20: 0 | D20: 黄哲睿 | E20: 302570 | F20: 数据研发 | G20: 架构管理 | H20: 1 | I20: 组长 | J20: 模型设计组 | K20: =C20+H20 -> 1
A21: 数据开发部 | B21: 数据开发部 | C21: 0 | D21: 林幸 | E21: 304814 | F21: 数据研发 | G21: 数据研发 | H21: 0 | I21: 骨干 | J21: 模型设计组 | K21: =C21+H21 -> 0
A22: 数据开发部 | B22: 数据开发部 | C22: 0 | D22: 姚志环 | E22: 303494 | F22: 数据研发 | G22: 数据研发 | H22: 0 | I22: 骨干 | J22: 模型设计组 | K22: =C22+H22 -> 0
A23: 数据开发部 | B23: 数据开发部 | C23: 0 | D23: 窦博文 | E23: 303569 | F23: 数据研发 | G23: 架构管理 | H23: 1 | J23: 模型设计组 | K23: =C23+H23 -> 1
A24: 数据开发部 | B24: 数据开发部 | C24: 0 | D24: 田振宇 | E24: 305405 | F24: 数据研发 | G24: 数据研发 | H24: 0 | J24: 模型设计组 | K24: =C24+H24 -> 0
A25: 数据开发部 | B25: 数据开发部 | C25: 0 | D25: 陆慧 | E25: 306252 | F25: 数据研发 | G25: 架构管理 | H25: 1 | I25: 骨干 | J25: 模型设计组 | K25: =C25+H25 -> 1
A26: 数据开发部 | B26: 数据开发部 | C26: 0 | D26: 周影 | E26: 303060 | F26: 数据研发 | G26: 数据研发 | H26: 0 | I26: 骨干 | J26: 模型设计组 | K26: =C26+H26 -> 0
A27: 数据开发部 | B27: 数据开发部 | C27: 0 | D27: 郑卞钰 | E27: 304792 | F27: 数据研发 | G27: 数据研发 | H27: 0 | J27: 模型设计组 | K27: =C27+H27 -> 0
A28: 数据开发部 | B28: 数据开发部 | C28: 0 | D28: 潘修滔 | E28: 305341 | F28: 数据研发 | G28: 数据研发 | H28: 0 | J28: 模型设计组 | K28: =C28+H28 -> 0
A29: 数据开发部 | B29: 数据开发部 | C29: 0 | D29: 赵雅婷 | E29: 306177 | F29: 数据研发 | G29: 数据研发 | H29: 0 | J29: 模型设计组 | K29: =C29+H29 -> 0
A30: 数据开发部 | B30: 数据开发部 | C30: 0 | D30: 兰昕蕾 | E30: 304064 | F30: 数据研发 | G30: 数据研发 | H30: 0 | I30: 组长 | J30: 数仓开发组 | K30: =C30+H30 -> 0
A31: 数据开发部 | B31: 数据开发部 | C31: 0 | D31: 袁凯 | E31: 305432 | F31: 数据研发 | G31: 数据研发 | H31: 0 | J31: 数仓开发组 | K31: =C31+H31 -> 0
A32: 数据开发部 | B32: 数据开发部 | C32: 0 | D32: 王萌萌 | E32: 306175 | F32: 数据研发 | G32: 数据研发 | H32: 0 | J32: 数仓开发组 | K32: =C32+H32 -> 0
A33: 数据开发部 | B33: 数据开发部 | C33: 0 | D33: 连静 | E33: 306532 | F33: 数据研发 | G33: 数据研发 | H33: 0 | J33: 数仓开发组 | K33: =C33+H33 -> 0
A34: 数据开发部 | B34: 数据开发部 | C34: 0 | D34: 曹婕 | E34: 305401 | F34: 数据研发 | G34: 数据研发 | H34: 0 | J34: 数仓开发组 | K34: =C34+H34 -> 0
A35: 数据开发部 | B35: 数据开发部 | C35: 0 | D35: 李禹凝 | E35: 306190 | F35: 数据研发 | G35: 数据研发 | H35: 0 | J35: 数仓开发组 | K35: =C35+H35 -> 0
A36: 数据开发部 | B36: 数据开发部 | C36: 0 | D36: 吴越 | E36: 307139 | F36: 数据研发 | G36: 数据研发 | H36: 0 | J36: 数仓开发组 | K36: =C36+H36 -> 0
A37: 数据开发部 | B37: 数据开发部 | C37: 0 | D37: 诸倩铷 | E37: 306187 | F37: 数据研发 | G37: 数据研发 | H37: 0 | J37: 数仓开发组 | K37: =C37+H37 -> 0
A38: 数据开发部 | B38: 数据开发部 | C38: 0 | D38: 罗仁杰 | E38: 319957 | F38: 数据研发 | G38: 数据研发 | H38: 0 | I38: 组长 | J38: 数据接入组 | K38: =C38+H38 -> 0
A39: 数据开发部 | B39: 数据开发部 | C39: 0 | D39: 李卓辉 | E39: 302476 | F39: 数据研发 | G39: 数据研发 | H39: 0 | J39: 数据接入组 | K39: =C39+H39 -> 0
A40: 数据开发部 | B40: 数据开发部 | C40: 0 | D40: 李凯文 | E40: 305481 | F40: 数据研发 | G40: 数据研发 | H40: 0 | J40: 数据接入组 | K40: =C40+H40 -> 0
...
