Workbook

Sheet Sheet4
A1: 事项类型 | B1: (多项)
A2: 所属的ADPM需求 | B2: (多项)
A4: 用人科室 | B4: 求和项:工时（小时） | F4: 用人科室 | G4: 总人天数 | H4: 总人天数 | I4: 应关联ADPM人天数 | J4: 关联ADPM需求工时数量 | K4: 关联ADPM需求人天数量 | L4: 比例
A5: 数据开发部 | B5: 300.75 | F5: 数据测试部 | G5: 278.4499 | H5: 39.87 | I5: =G5/8.5 -> 32.758812 | K5: =J5/8.5 -> 0 | L5: =K5/I5 -> 0
A6: 数据平台部 | B6: 349.1333 | F6: 数据开发部 | G6: 1878.2662 | H6: 410.24 | I6: =G6/8.5 -> 220.97249 | J6: 300.75 | K6: =J6/8.5 -> 35.382353 | L6: =K6/I6 -> 0.16012107
A7: 信息管理部 | B7: 280.5 | F7: 数据平台部 | G7: 1225.3331 | H7: 241.66 | I7: =G7/8.5 -> 144.15684 | J7: 349.1333 | K7: =J7/8.5 -> 41.074506 | L7: =K7/I7 -> 0.2849293
A8: 智能应用二部 | B8: 76.5 | F8: 智能平台部 | G8: 160.6835 | H8: 37 | I8: =G8/8.5 -> 18.903941 | K8: =J8/8.5 -> 0 | L8: =K8/I8 -> 0
A9: 智能应用一部 | B9: 76.5 | F9: 智能应用二部 | G9: 919.4165 | H9: 201.5 | I9: =G9/8.5 -> 108.16665 | J9: 76.5 | K9: =J9/8.5 -> 9 | L9: =K9/I9 -> 0.083204946
A10: 总计 | B10: 1083.3833 | F10: 智能应用一部 | G10: 860.6997 | H10: 141.41 | I10: =G10/8.5 -> 101.25879 | J10: 76.5 | K10: =J10/8.5 -> 9 | L10: =K10/I10 -> 0.088881174

Sheet 数管部工时明细
A1: 工作日期 | B1: 姓名 | C1: 工号 | D1: 所属科室 | E1: 所属分组 | F1: 任务描述 | G1: 应用系统 | H1: 批次 | I1: 所属的ADPM需求 | J1: 工作类型 | K1: 工时（小时） | L1: 事项类型
A2: 46106.699 | B2: 崔建文 | C2: 304059 | D2: 智能应用一部 | E2: =VLOOKUP(B2,'人员清单-202603'!D:J,7,FALSE) -> 对公应用组 | F2: 反诈机器学习模型0327版本开发测试 | I2: 关于反电诈管理项目的需求 | K2: 8.5 | L2: 开发（含模型、应用、数仓等）
A3: 46106.661 | B3: 沈子新 | C3: 307311 | D3: 智能应用一部 | E3: =VLOOKUP(B3,'人员清单-202603'!D:J,7,FALSE) -> 对公应用组 | F3: 信贷场景MVP版本327版本开发 | K3: 8.5 | L3: 项目管理（含外包管理）
A4: 46106.596 | B4: 张雨轩 | C4: 307357 | D4: 智能应用一部 | E4: =VLOOKUP(B4,'人员清单-202603'!D:J,7,FALSE) -> 对公应用组 | F4: 生产_智能问数实体召回策略优化 | K4: 8 | L4: 开发（含模型、应用、数仓等）
A5: 46106.573 | B5: 吕晶 | C5: 307442 | D5: 智能应用一部 | E5: =VLOOKUP(B5,'人员清单-202603'!D:J,7,FALSE) -> 零售应用组 | F5: 中试基地材料准备 | K5: 8.5 | L5: 其他
A6: 46106.416 | B6: 赵家乐 | C6: 307628 | D6: 智能应用一部 | E6: =VLOOKUP(B6,'人员清单-202603'!D:J,7,FALSE) -> 对公应用组 | F6: 流水鉴真场景327版本开发 | K6: 4.25 | L6: 生产运维
A7: 46106.416 | B7: 赵家乐 | C7: 307628 | D7: 智能应用一部 | E7: =VLOOKUP(B7,'人员清单-202603'!D:J,7,FALSE) -> 对公应用组 | F7: 信贷场景MVP版本327版本开发 | K7: 4.25 | L7: 项目管理（含外包管理）
A8: 46106.384 | B8: 陈彦百 | C8: 307310 | D8: 智能应用一部 | E8: =VLOOKUP(B8,'人员清单-202603'!D:J,7,FALSE) -> 对公应用组 | F8: 智能问数标准化取数工具封装(基于Langchain) | K8: 4.25 | L8: 开发（含模型、应用、数仓等）
A9: 46106.384 | B9: 陈彦百 | C9: 307310 | D9: 智能应用一部 | E9: =VLOOKUP(B9,'人员清单-202603'!D:J,7,FALSE) -> 对公应用组 | F9: AI需求分发/评审 | K9: 4.25 | L9: 设计（含可行性方案、概设、详设等）
A10: 46106.381 | B10: 朱嘉玮 | C10: 307441 | D10: 智能应用一部 | E10: =VLOOKUP(B10,'人员清单-202603'!D:J,7,FALSE) -> 零售应用组 | F10: 创景AI客户经营 | K10: 8.5 | L10: 设计（含可行性方案、概设、详设等）
A11: 46106.376 | B11: 祁鑫 | C11: 304932 | D11: 智能应用一部 | E11: =VLOOKUP(B11,'人员清单-202603'!D:J,7,FALSE) -> 对公应用组 | F11: 信贷场景MVP327版本上线准备 | K11: 8.5 | L11: 评审（含架构评审、代码评审、CAB等）
A12: 46106.368 | B12: 陈睿菁 | C12: 307451 | D12: 智能应用一部 | E12: =VLOOKUP(B12,'人员清单-202603'!D:J,7,FALSE) -> 对公应用组 | F12: 信贷场景MVP版本327版本开发 | K12: 8.5 | L12: 项目管理（含外包管理）
A13: 46106.361 | B13: 宛蕾 | C13: 307447 | D13: 智能应用一部 | E13: =VLOOKUP(B13,'人员清单-202603'!D:J,7,FALSE) -> 零售应用组 | F13: 【AI客户经营】智能外呼分析 | K13: 8.5 | L13: 其他
A14: 46106.349 | B14: 许天凝 | C14: 306180 | D14: 智能应用一部 | E14: =VLOOKUP(B14,'人员清单-202603'!D:J,7,FALSE) -> 零售应用组 | F14: 【办公助手】测评与知识运营协助 | K14: 8.5 | L14: 测试（含模型、应用、数仓等）
A15: 46106.326 | B15: 张镓奇 | C15: 304773 | D15: 智能应用一部 | E15: =VLOOKUP(B15,'人员清单-202603'!D:J,7,FALSE) -> 对公应用组 | F15: 智能问数标准化取数工具封装(基于Langchain) | K15: 8.5 | L15: 开发（含模型、应用、数仓等）
A16: 46105.793 | B16: 杨婧 | C16: 304304 | D16: 智能应用一部 | E16: =VLOOKUP(B16,'人员清单-202603'!D:J,7,FALSE) -> 对公应用组 | F16: 0327版本服务器申请与上线评审准备 | G16: 尽调报告助手 | I16: 关于优化AI原生的智能化尽调的需求 | K16: 2.8333 | L16: 生产运维
A17: 46105.793 | B17: 杨婧 | C17: 304304 | D17: 智能应用一部 | E17: =VLOOKUP(B17,'人员清单-202603'!D:J,7,FALSE) -> 对公应用组 | F17: 长文本智能分析mq更换 | K17: 2.8333 | L17: 项目管理（含外包管理）
A18: 46105.793 | B18: 杨婧 | C18: 304304 | D18: 智能应用一部 | E18: =VLOOKUP(B18,'人员清单-202603'!D:J,7,FALSE) -> 对公应用组 | F18: AI需求分发/评审 | K18: 2.8333 | L18: 设计（含可行性方案、概设、详设等）
A19: 46105.596 | B19: 张雨轩 | C19: 307357 | D19: 智能应用一部 | E19: =VLOOKUP(B19,'人员清单-202603'!D:J,7,FALSE) -> 对公应用组 | F19: 生产_智能问数实体召回策略优化 | K19: 8 | L19: 开发（含模型、应用、数仓等）
A20: 46105.417 | B20: 沈子新 | C20: 307311 | D20: 智能应用一部 | E20: =VLOOKUP(B20,'人员清单-202603'!D:J,7,FALSE) -> 对公应用组 | F20: 信贷场景MVP版本327版本开发 | K20: 8.5 | L20: 项目管理（含外包管理）
A21: 46105.404 | B21: 崔建文 | C21: 304059 | D21: 智能应用一部 | E21: =VLOOKUP(B21,'人员清单-202603'!D:J,7,FALSE) -> 对公应用组 | F21: 绿色金融业务管理项目大模型场景费用预算与资源规划 | I21: 绿色金融业务管理系统 | K21: 4.25 | L21: 设计（含可行性方案、概设、详设等）
A22: 46105.404 | B22: 崔建文 | C22: 304059 | D22: 智能应用一部 | E22: =VLOOKUP(B22,'人员清单-202603'!D:J,7,FALSE) -> 对公应用组 | F22: 反诈机器学习模型0327版本开发测试 | I22: 关于反电诈管理项目的需求 | K22: 4.25 | L22: 开发（含模型、应用、数仓等）
A23: 46105.401 | B23: 陈睿菁 | C23: 307451 | D23: 智能应用一部 | E23: =VLOOKUP(B23,'人员清单-202603'!D:J,7,FALSE) -> 对公应用组 | F23: 信贷场景MVP版本327版本开发 | K23: 8.5 | L23: 项目管理（含外包管理）
A24: 46105.382 | B24: 朱嘉玮 | C24: 307441 | D24: 智能应用一部 | E24: =VLOOKUP(B24,'人员清单-202603'!D:J,7,FALSE) -> 零售应用组 | F24: 创景AI客户经营 | K24: 8.5 | L24: 设计（含可行性方案、概设、详设等）
A25: 46105.381 | B25: 占桐 | C25: 307307 | D25: 智能应用一部 | E25: =VLOOKUP(B25,'人员清单-202603'!D:J,7,FALSE) -> 零售应用组 | F25: 创景AI客户经营 | K25: 8.5 | L25: 设计（含可行性方案、概设、详设等）
A26: 46105.369 | B26: 陈彦百 | C26: 307310 | D26: 智能应用一部 | E26: =VLOOKUP(B26,'人员清单-202603'!D:J,7,FALSE) -> 对公应用组 | F26: AI需求分发/评审 | K26: 8.5 | L26: 设计（含可行性方案、概设、详设等）
A27: 46105.368 | B27: 吕晶 | C27: 307442 | D27: 智能应用一部 | E27: =VLOOKUP(B27,'人员清单-202603'!D:J,7,FALSE) -> 零售应用组 | F27: 远银场景大模型 | K27: 8.5 | L27: 设计（含可行性方案、概设、详设等）
A28: 46105.368 | B28: 祁鑫 | C28: 304932 | D28: 智能应用一部 | E28: =VLOOKUP(B28,'人员清单-202603'!D:J,7,FALSE) -> 对公应用组 | F28: 信贷场景MVP327版本上线准备 | K28: 4.25 | L28: 评审（含架构评审、代码评审、CAB等）
A29: 46105.366 | B29: 祁鑫 | C29: 304932 | D29: 智能应用一部 | E29: =VLOOKUP(B29,'人员清单-202603'!D:J,7,FALSE) -> 对公应用组 | F29: 信贷场景MVP版本327版本开发 | K29: 4.25 | L29: 项目管理（含外包管理）
A30: 46105.366 | B30: 赵家乐 | C30: 307628 | D30: 智能应用一部 | E30: =VLOOKUP(B30,'人员清单-202603'!D:J,7,FALSE) -> 对公应用组 | F30: 流水鉴真场景327版本开发 | K30: 4.25 | L30: 生产运维
A31: 46105.366 | B31: 赵家乐 | C31: 307628 | D31: 智能应用一部 | E31: =VLOOKUP(B31,'人员清单-202603'!D:J,7,FALSE) -> 对公应用组 | F31: 信贷场景MVP版本327版本开发 | K31: 4.25 | L31: 项目管理（含外包管理）
A32: 46105.366 | B32: 宛蕾 | C32: 307447 | D32: 智能应用一部 | E32: =VLOOKUP(B32,'人员清单-202603'!D:J,7,FALSE) -> 零售应用组 | F32: 【AI客户经营】智能外呼分析 | K32: 8.5 | L32: 其他
A33: 46105.356 | B33: 许天凝 | C33: 306180 | D33: 智能应用一部 | E33: =VLOOKUP(B33,'人员清单-202603'!D:J,7,FALSE) -> 零售应用组 | F33: 【例行工作】知识运营 | K33: 4.25 | L33: 项目管理（含外包管理）
A34: 46105.356 | B34: 许天凝 | C34: 306180 | D34: 智能应用一部 | E34: =VLOOKUP(B34,'人员清单-202603'!D:J,7,FALSE) -> 零售应用组 | F34: 【办公助手】测评与知识运营协助 | K34: 4.25 | L34: 测试（含模型、应用、数仓等）
A35: 46105.323 | B35: 张镓奇 | C35: 304773 | D35: 智能应用一部 | E35: =VLOOKUP(B35,'人员清单-202603'!D:J,7,FALSE) -> 对公应用组 | F35: 智能问数标准化取数工具封装(基于Langchain) | K35: 8.5 | L35: 开发（含模型、应用、数仓等）
A36: 46104.659 | B36: 崔建文 | C36: 304059 | D36: 智能应用一部 | E36: =VLOOKUP(B36,'人员清单-202603'!D:J,7,FALSE) -> 对公应用组 | F36: 反诈机器学习模型0327版本开发测试 | I36: 关于反电诈管理项目的需求 | K36: 4.25 | L36: 开发（含模型、应用、数仓等）
A37: 46104.659 | B37: 崔建文 | C37: 304059 | D37: 智能应用一部 | E37: =VLOOKUP(B37,'人员清单-202603'!D:J,7,FALSE) -> 对公应用组 | F37: 绿色金融业务管理项目大模型场景费用预算与资源规划 | I37: 绿色金融业务管理系统 | K37: 4.25 | L37: 设计（含可行性方案、概设、详设等）
A38: 46104.613 | B38: 许天凝 | C38: 306180 | D38: 智能应用一部 | E38: =VLOOKUP(B38,'人员清单-202603'!D:J,7,FALSE) -> 零售应用组 | F38: 【办公助手】测评与知识运营协助 | K38: 4.25 | L38: 测试（含模型、应用、数仓等）
A39: 46104.608 | B39: 杨婧 | C39: 304304 | D39: 智能应用一部 | E39: =VLOOKUP(B39,'人员清单-202603'!D:J,7,FALSE) -> 对公应用组 | F39: AI需求分发/评审 | K39: 4.25 | L39: 设计（含可行性方案、概设、详设等）
A40: 46104.608 | B40: 杨婧 | C40: 304304 | D40: 智能应用一部 | E40: =VLOOKUP(B40,'人员清单-202603'!D:J,7,FALSE) -> 对公应用组 | F40: 长文本智能分析mq更换 | K40: 4.25 | L40: 项目管理（含外包管理）
...

Sheet 人员清单-202603
A1: 实际内设部 | B1: EHR内设部 | C1: 内设部是否变动 | D1: 姓名 | E1: 工号 | F1: 现岗位 | G1: 拟岗位 | H1: 岗位是否变动 | I1: 现角色标签 （组长/骨干） | J1: 拟分组
A2: 信息管理部 | B2: 信息管理部 | C2: 0 | D2: 舒宝龙 | E2: 305069 | F2: 数据分析 | G2: 数据分析 | H2: 0 | I2: 组长 | J2: 负责人 | K2: =C2+H2 -> 0
A3: 信息管理部 | B3: 信息管理部 | C3: 0 | D3: 任若琳 | E3: 307309 | F3: 数据分析 | G3: 需求分析 | H3: 1 | J3: 服务管理组 | K3: =C3+H3 -> 1
A4: 信息管理部 | B4: 信息管理部 | C4: 0 | D4: 成绘茜 | E4: 307444 | F4: 数据分析 | G4: 需求分析 | H4: 1 | J4: 服务管理组 | K4: =C4+H4 -> 1
A5: 信息管理部 | B5: 信息管理部 | C5: 0 | D5: 陆应佳玥 | E5: 305199 | F5: 数据分析 | G5: 需求分析 | H5: 1 | J5: 服务管理组 | K5: =C5+H5 -> 1
A6: 信息管理部 | B6: 信息管理部 | C6: 0 | D6: 李小萌 | E6: 306533 | F6: 数据分析 | G6: 需求分析 | H6: 1 | J6: 服务管理组 | K6: =C6+H6 -> 1
A7: 信息管理部 | B7: 信息管理部 | C7: 0 | D7: 宋轲 | E7: 307028 | F7: 数据分析 | G7: 数据分析 | H7: 0 | J7: 服务支持组 | K7: =C7+H7 -> 0
A8: 信息管理部 | B8: 信息管理部 | C8: 0 | D8: 张文婉 | E8: 304804 | F8: 数据分析 | G8: 数据分析 | H8: 0 | J8: 服务支持组 | K8: =C8+H8 -> 0
A9: 信息管理部 | B9: 信息管理部 | C9: 0 | D9: 刘雅雯 | E9: 307443 | F9: 数据分析 | G9: 数据分析 | H9: 0 | J9: 服务支持组 | K9: =C9+H9 -> 0
A10: 信息管理部 | B10: 信息管理部 | C10: 0 | D10: 孙菡悦 | E10: 305446 | F10: 数据分析 | G10: 数据分析 | H10: 0 | J10: 服务支持组 | K10: =C10+H10 -> 0
A11: 信息管理部 | B11: 信息管理部 | C11: 0 | D11: 刘思言 | E11: 305409 | F11: 数据分析 | G11: 数据分析 | H11: 0 | J11: 服务支持组 | K11: =C11+H11 -> 0
A12: 信息管理部 | B12: 信息管理部 | C12: 0 | D12: 谢丹伶 | E12: 305588 | F12: 数据分析 | G12: 数据分析 | H12: 0 | J12: 服务支持组 | K12: =C12+H12 -> 0
A13: 数据测试部 | B13: 综合管理部 | C13: 1 | D13: 杨萍 | E13: 306253 | F13: 数据测试 | G13: 负责人 | H13: 1 | I13: 组长 | J13: 负责人 | K13: =C13+H13 -> 2
A14: 数据测试部 | B14: 综合管理部 | C14: 1 | D14: 马亦沁 | E14: 305419 | F14: 数据测试 | G14: 数据测试 | H14: 0 | J14: 测试管理组 | K14: =C14+H14 -> 1
A15: 数据测试部 | B15: 综合管理部 | C15: 1 | D15: 蒋书润 | E15: 306762 | F15: 数据测试 | G15: 数据测试 | H15: 0 | J15: 测试管理组 | K15: =C15+H15 -> 1
A16: 数据测试部 | B16: 综合管理部 | C16: 1 | D16: 陈世辉 | E16: 306537 | F16: 数据测试 | G16: 数据测试 | H16: 0 | I16: 骨干 | J16: 测试管理组 | K16: =C16+H16 -> 1
A17: 数据测试部 | B17: 综合管理部 | C17: 1 | D17: 曹翔 | E17: 306530 | F17: 数据测试 | G17: 数据测试 | H17: 0 | J17: 测试管理组 | K17: =C17+H17 -> 1
A18: 数据开发部 | B18: 数据开发部 | C18: 0 | D18: 顾恺 | E18: 319914 | F18: 负责人 | G18: 负责人 | H18: 0 | J18: 负责人 | K18: =C18+H18 -> 0
A19: 数据开发部 | B19: 数据开发部 | C19: 0 | D19: 杨青 | E19: 302330 | F19: 数据研发 | G19: 架构管理 | H19: 1 | J19: 协管 | K19: =C19+H19 -> 1
A20: 数据开发部 | B20: 数据开发部 | C20: 0 | D20: 黄哲睿 | E20: 302570 | F20: 数据研发 | G20: 架构管理 | H20: 1 | I20: 组长 | J20: 模型设计组 | K20: =C20+H20 -> 1
A21: 数据开发部 | B21: 数据开发部 | C21: 0 | D21: 林幸 | E21: 304814 | F21: 数据研发 | G21: 数据研发 | H21: 0 | I21: 骨干 | J21: 模型设计组 | K21: =C21+H21 -> 0
A22: 数据开发部 | B22: 数据开发部 | C22: 0 | D22: 姚志环 | E22: 303494 | F22: 数据研发 | G22: 数据研发 | H22: 0 | I22: 骨干 | J22: 模型设计组 | K22: =C22+H22 -> 0
A23: 数据开发部 | B23: 数据开发部 | C23: 0 | D23: 窦博文 | E23: 303569 | F23: 数据研发 | G23: 架构管理 | H23: 1 | J23: 模型设计组 | K23: =C23+H23 -> 1
A24: 数据开发部 | B24: 数据开发部 | C24: 0 | D24: 田振宇 | E24: 305405 | F24: 数据研发 | G24: 数据研发 | H24: 0 | J24: 模型设计组 | K24: =C24+H24 -> 0
A25: 数据开发部 | B25: 数据开发部 | C25: 0 | D25: 陆慧 | E25: 306252 | F25: 数据研发 | G25: 架构管理 | H25: 1 | I25: 骨干 | J25: 模型设计组 | K25: =C25+H25 -> 1
A26: 数据开发部 | B26: 数据开发部 | C26: 0 | D26: 周影 | E26: 303060 | F26: 数据研发 | G26: 数据研发 | H26: 0 | I26: 骨干 | J26: 模型设计组 | K26: =C26+H26 -> 0
A27: 数据开发部 | B27: 数据开发部 | C27: 0 | D27: 郑卞钰 | E27: 304792 | F27: 数据研发 | G27: 数据研发 | H27: 0 | J27: 模型设计组 | K27: =C27+H27 -> 0
A28: 数据开发部 | B28: 数据开发部 | C28: 0 | D28: 潘修滔 | E28: 305341 | F28: 数据研发 | G28: 数据研发 | H28: 0 | J28: 模型设计组 | K28: =C28+H28 -> 0
A29: 数据开发部 | B29: 数据开发部 | C29: 0 | D29: 赵雅婷 | E29: 306177 | F29: 数据研发 | G29: 数据研发 | H29: 0 | J29: 模型设计组 | K29: =C29+H29 -> 0
A30: 数据开发部 | B30: 数据开发部 | C30: 0 | D30: 兰昕蕾 | E30: 304064 | F30: 数据研发 | G30: 数据研发 | H30: 0 | I30: 组长 | J30: 数仓开发组 | K30: =C30+H30 -> 0
A31: 数据开发部 | B31: 数据开发部 | C31: 0 | D31: 袁凯 | E31: 305432 | F31: 数据研发 | G31: 数据研发 | H31: 0 | J31: 数仓开发组 | K31: =C31+H31 -> 0
A32: 数据开发部 | B32: 数据开发部 | C32: 0 | D32: 王萌萌 | E32: 306175 | F32: 数据研发 | G32: 数据研发 | H32: 0 | J32: 数仓开发组 | K32: =C32+H32 -> 0
A33: 数据开发部 | B33: 数据开发部 | C33: 0 | D33: 连静 | E33: 306532 | F33: 数据研发 | G33: 数据研发 | H33: 0 | J33: 数仓开发组 | K33: =C33+H33 -> 0
A34: 数据开发部 | B34: 数据开发部 | C34: 0 | D34: 曹婕 | E34: 305401 | F34: 数据研发 | G34: 数据研发 | H34: 0 | J34: 数仓开发组 | K34: =C34+H34 -> 0
A35: 数据开发部 | B35: 数据开发部 | C35: 0 | D35: 李禹凝 | E35: 306190 | F35: 数据研发 | G35: 数据研发 | H35: 0 | J35: 数仓开发组 | K35: =C35+H35 -> 0
A36: 数据开发部 | B36: 数据开发部 | C36: 0 | D36: 吴越 | E36: 307139 | F36: 数据研发 | G36: 数据研发 | H36: 0 | J36: 数仓开发组 | K36: =C36+H36 -> 0
A37: 数据开发部 | B37: 数据开发部 | C37: 0 | D37: 诸倩铷 | E37: 306187 | F37: 数据研发 | G37: 数据研发 | H37: 0 | J37: 数仓开发组 | K37: =C37+H37 -> 0
A38: 数据开发部 | B38: 数据开发部 | C38: 0 | D38: 罗仁杰 | E38: 319957 | F38: 数据研发 | G38: 数据研发 | H38: 0 | I38: 组长 | J38: 数据接入组 | K38: =C38+H38 -> 0
A39: 数据开发部 | B39: 数据开发部 | C39: 0 | D39: 李卓辉 | E39: 302476 | F39: 数据研发 | G39: 数据研发 | H39: 0 | J39: 数据接入组 | K39: =C39+H39 -> 0
A40: 数据开发部 | B40: 数据开发部 | C40: 0 | D40: 李凯文 | E40: 305481 | F40: 数据研发 | G40: 数据研发 | H40: 0 | J40: 数据接入组 | K40: =C40+H40 -> 0
...
