Workbook

Sheet 2.1 全量203人-11月
A1: 序号 | B1: 姓名 | C1: 基本信息 | I1: 岗位信息 | O1: 党工团任职情况 | R1: 行内、行外荣誉 | S1: 主动学习与对外输出 | X1: 考勤数据 | AD1: 工作饱和度量化（开发类岗位） | AL1: 综合主观评价 | AS1: 备注 | AT1: 加工指标
C2: 团队 | D2: 组 | E2: 性别 | F2: 累计工龄 | G2: 最高学历 | H2: 最高学历毕业院校 | I2: 科长/组长/骨干标识 | J2: 产品经理/架构师标识 | K2: 产品经理/架构师负责应用个数 | L2: 岗位变动次数 | M2: 现在的工作岗位 | N2: 校招/社招标识 | O2: 党组织 | P2: 工会小组 | Q2: 团委 | S2: 年度参加培训次数 | T2: 查看知识库会议纪要次数(3个月) | U2: 年度部门内培训次数 | V2: 年度部门外培训次数 | W2: 近2年带教人数 | X2: 平均加班时长 | Y2: 工作时长高于部门均值 | Z2: 1h以下 | AA2: 加班1-2h频次 | AB2: 加班2-4h频次 | AC2: 加班4h以上频次 | AD2: 牵头项目数量 | AE2: 牵头需求数量 | AF2: 主管应用系统数量（近六个月有变更的数量） | AG2: 新paso体系参与应用数量 | AH2: 二季度变更任务数 | AI2: 三季度变更任务数 | AK2: 饱和度量化 不饱和：平均加班时长1h以下/无变更任务无主管应用非组长骨干/科长评定不饱和 超负荷：季度变更任务≥10/加班4H以上超过30次/平均加班时长3H以上/科长评定超负荷 | AL2: 领导力 | AM2: 专业能力 | AN2: 工作态度 | AO2: 团队合作 | AP2: 累计 | AQ2: 归类 | AR2: 其他特质 | AT2: 饱和度指标
A3: 1 | B3: 黄哲睿 | C3: 数据开发部 | D3: 模型设计组 | E3: 男 | F3: 8 | G3: 大学本科 | H3: 南京大学 | I3: 组长 | J3: 架构师 | K3: 2 | L3: 0 | M3: 数据研发 | N3: 校园招聘 | Q3: 团委书记 | R3: 24数据文化优秀贡献者 | S3: =VLOOKUP(B3,'[2]62人'!$B:$R,17,FALSE) -> 1 | T3: 5 | X3: =VLOOKUP(B3,[4]考勤分析!$A:$I,4,FALSE) -> 4.6505208 | Y3: =VLOOKUP(B3,[4]考勤分析!$A:$I,5,FALSE) -> TRUE | Z3: =VLOOKUP(B3,[4]考勤分析!$A:$I,6,FALSE) -> 9 | AA3: =VLOOKUP(B3,[4]考勤分析!$A:$I,7,FALSE) -> 2 | AB3: =VLOOKUP(B3,[4]考勤分析!$A:$I,8,FALSE) -> 20 | AC3: =VLOOKUP(B3,[4]考勤分析!$A:$I,9,FALSE) -> 41 | AD3: 0 | AE3: 1 | AF3: 0 | AG3: 1 | AH3: 0 | AI3: 0 | AK3: =VLOOKUP(B3,[3]总表!$B:$W,22,FALSE) -> 超负荷 | AL3: 3 | AM3: 3 | AN3: 2 | AO3: 2 | AP3: =SUM(AL3:AO3) -> 10 | AQ3: 4-高潜培养对象 | AR3: 团队内人缘较好，有意见领袖的潜质 | AT3: =COUNTA(I3,J3,K3,O3,P3,Q3,W3) -> 4
A4: 2 | B4: 陆慧 | C4: 数据开发部 | D4: 模型设计组 | E4: 女 | F4: 14 | G4: 研究生 | H4: 南京大学 | I4: 骨干 | J4: 架构师 | K4: 5 | L4: 0 | M4: 数据研发 | N4: 社会招聘 | S4: =VLOOKUP(B4,'[2]62人'!$B:$R,17,FALSE) -> 2 | T4: 0 | W4: 1 | X4: =VLOOKUP(B4,[4]考勤分析!$A:$I,4,FALSE) -> 3.0414665 | Y4: =VLOOKUP(B4,[4]考勤分析!$A:$I,5,FALSE) -> TRUE | Z4: =VLOOKUP(B4,[4]考勤分析!$A:$I,6,FALSE) -> 16 | AA4: =VLOOKUP(B4,[4]考勤分析!$A:$I,7,FALSE) -> 16 | AB4: =VLOOKUP(B4,[4]考勤分析!$A:$I,8,FALSE) -> 24 | AC4: =VLOOKUP(B4,[4]考勤分析!$A:$I,9,FALSE) -> 12 | AD4: 0 | AE4: 0 | AF4: 0 | AG4: 1 | AH4: 0 | AI4: 0 | AK4: =VLOOKUP(B4,[3]总表!$B:$W,22,FALSE) -> 适中 | AL4: 1 | AM4: 3 | AN4: 3 | AO4: 2 | AP4: =SUM(AL4:AO4) -> 9 | AQ4: 1.1-专业能力强，但领导力较弱 | AR4: 埋头苦干型
A5: 3 | B5: 罗仁杰 | C5: 数据开发部 | D5: 需求接入组 | E5: 男 | F5: 21 | G5: 大学本科 | H5: 兰州理工大学 | I5: 组长 | J5: 架构师 | K5: 1 | L5: 1 | M5: 数据研发 | N5: 社会招聘 | R5: 23五星质量奖 | S5: =VLOOKUP(B5,'[2]62人'!$B:$R,17,FALSE) -> 16 | T5: 0 | X5: =VLOOKUP(B5,[4]考勤分析!$A:$I,4,FALSE) -> 3.1066158 | Y5: =VLOOKUP(B5,[4]考勤分析!$A:$I,5,FALSE) -> TRUE | Z5: =VLOOKUP(B5,[4]考勤分析!$A:$I,6,FALSE) -> 8 | AA5: =VLOOKUP(B5,[4]考勤分析!$A:$I,7,FALSE) -> 19 | AB5: =VLOOKUP(B5,[4]考勤分析!$A:$I,8,FALSE) -> 32 | AC5: =VLOOKUP(B5,[4]考勤分析!$A:$I,9,FALSE) -> 12 | AD5: 0 | AE5: 5 | AF5: 1 | AG5: 1 | AH5: 24 | AI5: 13 | AK5: =VLOOKUP(B5,[3]总表!$B:$W,22,FALSE) -> 超负荷 | AL5: 1 | AM5: 2 | AN5: 1 | AO5: 2 | AP5: =SUM(AL5:AO5) -> 6 | AQ5: 3-不作为优先培养对象 | AR5: 敬业，工龄长缺乏内驱力下，职等较高
A6: 4 | B6: 李卓辉 | C6: 数据开发部 | D6: 需求接入组 | E6: 男 | F6: 19 | G6: 研究生 | H6: 华东师范大学 | L6: 1 | M6: 数据研发 | N6: 社会招聘 | S6: =VLOOKUP(B6,'[2]62人'!$B:$R,17,FALSE) -> 15 | T6: 0 | X6: =VLOOKUP(B6,[4]考勤分析!$A:$I,4,FALSE) -> 2.1227375 | Y6: =VLOOKUP(B6,[4]考勤分析!$A:$I,5,FALSE) -> FALSE | Z6: =VLOOKUP(B6,[4]考勤分析!$A:$I,6,FALSE) -> 5 | AA6: =VLOOKUP(B6,[4]考勤分析!$A:$I,7,FALSE) -> 12 | AB6: =VLOOKUP(B6,[4]考勤分析!$A:$I,8,FALSE) -> 45 | AC6: =VLOOKUP(B6,[4]考勤分析!$A:$I,9,FALSE) -> 0 | AD6: 0 | AE6: 0 | AF6: 0 | AG6: 1 | AH6: 0 | AI6: 1 | AK6: =VLOOKUP(B6,[3]总表!$B:$W,22,FALSE) -> 不饱和 | AL6: 1 | AM6: 2 | AN6: 1 | AO6: 1 | AP6: =SUM(AL6:AO6) -> 5 | AQ6: 3-不作为优先培养对象 | AR6: 敬业，工龄长缺乏内驱力，职等较高
A7: 5 | B7: 兰昕蕾 | C7: 数据开发部 | D7: 数仓开发组 | E7: 女 | F7: 5 | G7: 研究生 | H7: 华东师范大学 | I7: 组长 | L7: 0 | M7: 数据研发 | N7: 校园招聘 | S7: =VLOOKUP(B7,'[2]62人'!$B:$R,17,FALSE) -> 14 | T7: 2 | U7: 3 | W7: 1 | X7: =VLOOKUP(B7,[4]考勤分析!$A:$I,4,FALSE) -> 3.9940217 | Y7: =VLOOKUP(B7,[4]考勤分析!$A:$I,5,FALSE) -> TRUE | Z7: =VLOOKUP(B7,[4]考勤分析!$A:$I,6,FALSE) -> 7 | AA7: =VLOOKUP(B7,[4]考勤分析!$A:$I,7,FALSE) -> 4 | AB7: =VLOOKUP(B7,[4]考勤分析!$A:$I,8,FALSE) -> 33 | AC7: =VLOOKUP(B7,[4]考勤分析!$A:$I,9,FALSE) -> 25 | AD7: 0 | AE7: 2 | AF7: 0 | AG7: 1 | AH7: 8 | AI7: 7 | AK7: =VLOOKUP(B7,[3]总表!$B:$W,22,FALSE) -> 超负荷 | AL7: 2 | AM7: 3 | AN7: 3 | AO7: 3 | AP7: =SUM(AL7:AO7) -> 11 | AQ7: 1.1-专业能力强，但领导力较弱 | AR7: 有思想、有潜力 值得培养
A8: 6 | B8: 邹小芳 | C8: 数据开发部 | D8: 数仓开发组 | E8: 女 | F8: 12 | G8: 大学本科 | H8: 江西财经大学 | I8: 组长 | L8: 0 | M8: 数据研发 | N8: 社会招聘 | S8: =VLOOKUP(B8,'[2]62人'!$B:$R,17,FALSE) -> 6 | T8: 0 | W8: 1 | X8: =VLOOKUP(B8,[4]考勤分析!$A:$I,4,FALSE) -> 3.2647607 | Y8: =VLOOKUP(B8,[4]考勤分析!$A:$I,5,FALSE) -> TRUE | Z8: =VLOOKUP(B8,[4]考勤分析!$A:$I,6,FALSE) -> 13 | AA8: =VLOOKUP(B8,[4]考勤分析!$A:$I,7,FALSE) -> 14 | AB8: =VLOOKUP(B8,[4]考勤分析!$A:$I,8,FALSE) -> 25 | AC8: =VLOOKUP(B8,[4]考勤分析!$A:$I,9,FALSE) -> 13 | AD8: 0 | AE8: 2 | AF8: 0 | AG8: 2 | AH8: 0 | AI8: 0 | AK8: =VLOOKUP(B8,[3]总表!$B:$W,22,FALSE) -> 超负荷 | AL8: 1 | AM8: 2 | AN8: 2 | AO8: 2 | AP8: =SUM(AL8:AO8) -> 7 | AQ8: 3-不作为优先培养对象 | AR8: 认真 没有出彩
A9: 7 | B9: 丁晨 | C9: 数据开发部 | D9: 数仓开发组 | E9: 男 | F9: 4 | G9: 研究生 | H9: 南京信息工程大学 | I9: 组长 | L9: 0 | M9: 数据研发 | N9: 校园招聘 | R9: 24五星质量奖 | S9: =VLOOKUP(B9,'[2]62人'!$B:$R,17,FALSE) -> 9 | T9: 1 | V9: 1 | X9: =VLOOKUP(B9,[4]考勤分析!$A:$I,4,FALSE) -> 3.8408638 | Y9: =VLOOKUP(B9,[4]考勤分析!$A:$I,5,FALSE) -> TRUE | Z9: =VLOOKUP(B9,[4]考勤分析!$A:$I,6,FALSE) -> 8 | AA9: =VLOOKUP(B9,[4]考勤分析!$A:$I,7,FALSE) -> 4 | AB9: =VLOOKUP(B9,[4]考勤分析!$A:$I,8,FALSE) -> 34 | AC9: =VLOOKUP(B9,[4]考勤分析!$A:$I,9,FALSE) -> 27 | AD9: 0 | AE9: 2 | AF9: 1 | AG9: 3 | AH9: 10 | AI9: 6 | AK9: =VLOOKUP(B9,[3]总表!$B:$W,22,FALSE) -> 超负荷 | AL9: 2 | AM9: 3 | AN9: 3 | AO9: 2 | AP9: =SUM(AL9:AO9) -> 10 | AQ9: 1.1-专业能力强，但领导力较弱 | AR9: 有思想、有潜力 值得培养
A10: 8 | B10: 周龙 | C10: 数据开发部 | D10: 应用开发组 | E10: 男 | F10: 10 | G10: 大学本科 | H10: 北京科技大学 | I10: 骨干 | J10: 产品经理 | K10: 2 | L10: 1 | M10: 数据研发 | N10: 社会招聘 | S10: =VLOOKUP(B10,'[2]62人'!$B:$R,17,FALSE) -> 7 | T10: 0 | W10: 1 | X10: =VLOOKUP(B10,[4]考勤分析!$A:$I,4,FALSE) -> 2.897921 | Y10: =VLOOKUP(B10,[4]考勤分析!$A:$I,5,FALSE) -> TRUE | Z10: =VLOOKUP(B10,[4]考勤分析!$A:$I,6,FALSE) -> 12 | AA10: =VLOOKUP(B10,[4]考勤分析!$A:$I,7,FALSE) -> 12 | AB10: =VLOOKUP(B10,[4]考勤分析!$A:$I,8,FALSE) -> 32 | AC10: =VLOOKUP(B10,[4]考勤分析!$A:$I,9,FALSE) -> 8 | AD10: 0 | AE10: 3 | AF10: 1 | AG10: 0 | AH10: 0 | AI10: 0 | AK10: =VLOOKUP(B10,[3]总表!$B:$W,22,FALSE) -> 超负荷 | AL10: 2 | AM10: 3 | AN10: 2 | AO10: 2 | AP10: =SUM(AL10:AO10) -> 9 | AQ10: 1.1-专业能力强，但领导力较弱 | AR10: 有一定思想 可被激发
A11: 9 | B11: 史朋飞 | C11: 数据平台部 | D11: 运维支持组 | E11: 男 | F11: 13 | G11: 大学本科 | H11: 河南理工大学 | I11: 组长 | J11: 架构师 | K11: 3 | L11: 0 | M11: 数据研发 | N11: 社会招聘 | S11: =VLOOKUP(B11,'[2]62人'!$B:$R,17,FALSE) -> 2 | T11: 0 | X11: =VLOOKUP(B11,[4]考勤分析!$A:$I,4,FALSE) -> 2.6378429 | Y11: =VLOOKUP(B11,[4]考勤分析!$A:$I,5,FALSE) -> TRUE | Z11: =VLOOKUP(B11,[4]考勤分析!$A:$I,6,FALSE) -> 11 | AA11: =VLOOKUP(B11,[4]考勤分析!$A:$I,7,FALSE) -> 4 | AB11: =VLOOKUP(B11,[4]考勤分析!$A:$I,8,FALSE) -> 45 | AC11: =VLOOKUP(B11,[4]考勤分析!$A:$I,9,FALSE) -> 4 | AD11: 0 | AE11: 0 | AF11: 1 | AG11: 5 | AH11: 2 | AI11: 2 | AK11: =VLOOKUP(B11,[3]总表!$B:$W,22,FALSE) -> 超负荷 | AL11: 2 | AM11: 3 | AN11: 3 | AO11: 2 | AP11: =SUM(AL11:AO11) -> 10 | AQ11: 1.1-专业能力强，但领导力较弱 | AR11: 社招入行，渴望被认可，工作积极性较强
A12: 10 | B12: 李天卓 | C12: 数据平台部 | D12: 运维支持组 | E12: 男 | F12: 6 | G12: 研究生 | H12: 上海师范大学 | I12: 骨干 | J12: 架构师 | K12: 2 | L12: 0 | M12: 数据研发 | N12: 校园招聘 | R12: 23技术能手 | S12: =VLOOKUP(B12,'[2]62人'!$B:$R,17,FALSE) -> 12 | T12: 0 | X12: =VLOOKUP(B12,[4]考勤分析!$A:$I,4,FALSE) -> 2.3013007 | Y12: =VLOOKUP(B12,[4]考勤分析!$A:$I,5,FALSE) -> TRUE | Z12: =VLOOKUP(B12,[4]考勤分析!$A:$I,6,FALSE) -> 9 | AA12: =VLOOKUP(B12,[4]考勤分析!$A:$I,7,FALSE) -> 30 | AB12: =VLOOKUP(B12,[4]考勤分析!$A:$I,8,FALSE) -> 17 | AC12: =VLOOKUP(B12,[4]考勤分析!$A:$I,9,FALSE) -> 7 | AD12: 0 | AE12: 0 | AF12: 2 | AG12: 1 | AH12: 0 | AI12: 1 | AK12: =VLOOKUP(B12,[3]总表!$B:$W,22,FALSE) -> 超负荷 | AL12: 1 | AM12: 2 | AN12: 2 | AO12: 2 | AP12: =SUM(AL12:AO12) -> 7 | AQ12: 3-不作为优先培养对象 | AR12: 技术型男生中表达较可的，踏实，工作有一定积极性
A13: 11 | B13: 曹宁远 | C13: 数据平台部 | D13: 工具开发组 | E13: 男 | F13: 6 | G13: 研究生 | H13: 北京理工大学 | I13: 组长 | J13: 架构师 | K13: 6 | L13: 0 | M13: 数据研发 | N13: 校园招聘 | S13: =VLOOKUP(B13,'[2]62人'!$B:$R,17,FALSE) -> 8 | T13: 0 | U13: 1 | V13: 1 | W13: 1 | X13: =VLOOKUP(B13,[4]考勤分析!$A:$I,4,FALSE) -> 1.4162366 | Y13: =VLOOKUP(B13,[4]考勤分析!$A:$I,5,FALSE) -> FALSE | Z13: =VLOOKUP(B13,[4]考勤分析!$A:$I,6,FALSE) -> 21 | AA13: =VLOOKUP(B13,[4]考勤分析!$A:$I,7,FALSE) -> 24 | AB13: =VLOOKUP(B13,[4]考勤分析!$A:$I,8,FALSE) -> 15 | AC13: =VLOOKUP(B13,[4]考勤分析!$A:$I,9,FALSE) -> 2 | AD13: 1 | AE13: 0 | AF13: 1 | AG13: 5 | AH13: 0 | AI13: 0 | AK13: =VLOOKUP(B13,[3]总表!$B:$W,22,FALSE) -> 适中 | AL13: 1 | AM13: 3 | AN13: 2 | AO13: 2 | AP13: =SUM(AL13:AO13) -> 8 | AQ13: 1.2-专业能力强，但领导力较弱，建议走技术路线 | AR13: 建议走技术线
A14: 12 | B14: 伍恒 | C14: 数据平台部 | D14: 工具开发组 | E14: 男 | F14: 8 | G14: 研究生 | H14: 武汉科技大学 | I14: 骨干 | L14: 0 | M14: 数据研发 | N14: 校园招聘 | R14: 23研究与创新奖 | S14: =VLOOKUP(B14,'[2]62人'!$B:$R,17,FALSE) -> 6 | T14: 0 | X14: =VLOOKUP(B14,[4]考勤分析!$A:$I,4,FALSE) -> 2.3839689 | Y14: =VLOOKUP(B14,[4]考勤分析!$A:$I,5,FALSE) -> TRUE | Z14: =VLOOKUP(B14,[4]考勤分析!$A:$I,6,FALSE) -> 12 | AA14: =VLOOKUP(B14,[4]考勤分析!$A:$I,7,FALSE) -> 32 | AB14: =VLOOKUP(B14,[4]考勤分析!$A:$I,8,FALSE) -> 5 | AC14: =VLOOKUP(B14,[4]考勤分析!$A:$I,9,FALSE) -> 10 | AD14: 1 | AE14: 1 | AF14: 2 | AG14: 2 | AH14: 11 | AI14: 38 | AK14: =VLOOKUP(B14,[3]总表!$B:$W,22,FALSE) -> 超负荷 | AL14: 1 | AM14: 3 | AN14: 2 | AO14: 2 | AP14: =SUM(AL14:AO14) -> 8 | AQ14: 1.2-专业能力强，但领导力较弱，建议走技术路线 | AR14: 建议走技术线
A15: 13 | B15: 王正超 | C15: 数据平台部 | D15: 应用开发组 | E15: 男 | F15: 6 | G15: 研究生 | H15: 北京交通大学 | I15: 骨干 | L15: 1 | M15: 数据研发 | N15: 校园招聘 | S15: =VLOOKUP(B15,'[2]62人'!$B:$R,17,FALSE) -> 9 | T15: 18 | U15: 2 | W15: 1 | X15: =VLOOKUP(B15,[4]考勤分析!$A:$I,4,FALSE) -> 3.1960769 | Y15: =VLOOKUP(B15,[4]考勤分析!$A:$I,5,FALSE) -> TRUE | Z15: =VLOOKUP(B15,[4]考勤分析!$A:$I,6,FALSE) -> 7 | AA15: =VLOOKUP(B15,[4]考勤分析!$A:$I,7,FALSE) -> 13 | AB15: =VLOOKUP(B15,[4]考勤分析!$A:$I,8,FALSE) -> 30 | AC15: =VLOOKUP(B15,[4]考勤分析!$A:$I,9,FALSE) -> 15 | AD15: 1 | AE15: 14 | AF15: 1 | AG15: 3 | AH15: 14 | AI15: 16 | AK15: =VLOOKUP(B15,[3]总表!$B:$W,22,FALSE) -> 超负荷 | AL15: 2 | AM15: 3 | AN15: 3 | AO15: 2 | AP15: =SUM(AL15:AO15) -> 10 | AQ15: 1.1-专业能力强，但领导力较弱 | AR15: 老黄牛类型
A16: 14 | B16: 嵇雅娟 | C16: 数据平台部 | D16: 应用开发组 | E16: 女 | F16: 11 | G16: 大学本科 | H16: 中国科学技术大学 | I16: 骨干 | L16: 1 | M16: 数据研发 | N16: 社会招聘 | S16: =VLOOKUP(B16,'[2]62人'!$B:$R,17,FALSE) -> 23 | T16: 0 | W16: 1 | X16: =VLOOKUP(B16,[4]考勤分析!$A:$I,4,FALSE) -> 1.9198387 | Y16: =VLOOKUP(B16,[4]考勤分析!$A:$I,5,FALSE) -> FALSE | Z16: =VLOOKUP(B16,[4]考勤分析!$A:$I,6,FALSE) -> 32 | AA16: =VLOOKUP(B16,[4]考勤分析!$A:$I,7,FALSE) -> 21 | AB16: =VLOOKUP(B16,[4]考勤分析!$A:$I,8,FALSE) -> 2 | AC16: =VLOOKUP(B16,[4]考勤分析!$A:$I,9,FALSE) -> 7 | AD16: 0 | AE16: 5 | AF16: 3 | AG16: 2 | AH16: 5 | AI16: 9 | AK16: =VLOOKUP(B16,[3]总表!$B:$W,22,FALSE) -> 适中 | AL16: 1 | AM16: 2 | AN16: 2 | AO16: 2 | AP16: =SUM(AL16:AO16) -> 7 | AQ16: 3-不作为优先培养对象 | AR16: 中规中矩
A17: 15 | B17: 鞠爱宁 | C17: 数据平台部 | D17: 数据服务组 | E17: 男 | F17: 8 | G17: 研究生 | H17: 上海大学 | I17: 组长 | J17: 架构师 | K17: 8 | L17: 1 | M17: 数据研发 | N17: 校园招聘 | R17: 24技术能手 | S17: =VLOOKUP(B17,'[2]62人'!$B:$R,17,FALSE) -> 5 | T17: 24 | U17: 1 | X17: =VLOOKUP(B17,[4]考勤分析!$A:$I,4,FALSE) -> 3.0539359 | Y17: =VLOOKUP(B17,[4]考勤分析!$A:$I,5,FALSE) -> TRUE | Z17: =VLOOKUP(B17,[4]考勤分析!$A:$I,6,FALSE) -> 4 | AA17: =VLOOKUP(B17,[4]考勤分析!$A:$I,7,FALSE) -> 8 | AB17: =VLOOKUP(B17,[4]考勤分析!$A:$I,8,FALSE) -> 37 | AC17: =VLOOKUP(B17,[4]考勤分析!$A:$I,9,FALSE) -> 16 | AD17: 0 | AE17: 1 | AF17: 1 | AG17: 2 | AH17: 10 | AI17: 11 | AK17: =VLOOKUP(B17,[3]总表!$B:$W,22,FALSE) -> 超负荷 | AL17: 2 | AM17: 3 | AN17: 2 | AO17: 2 | AP17: =SUM(AL17:AO17) -> 9 | AQ17: 1.1-专业能力强，但领导力较弱 | AR17: 渴望被认可，缺少机会
A18: 16 | B18: 魏佳翔 | C18: 数据平台部 | D18: 数据服务组 | E18: 男 | F18: 12 | G18: 大学本科 | H18: 大连海事大学 | I18: 组长 | J18: 架构师 | K18: 12 | L18: 1 | M18: 数据研发 | N18: 社会招聘 | S18: =VLOOKUP(B18,'[2]62人'!$B:$R,17,FALSE) -> 11 | T18: 0 | X18: =VLOOKUP(B18,[4]考勤分析!$A:$I,4,FALSE) -> 1.6090694 | Y18: =VLOOKUP(B18,[4]考勤分析!$A:$I,5,FALSE) -> FALSE | Z18: =VLOOKUP(B18,[4]考勤分析!$A:$I,6,FALSE) -> 30 | AA18: =VLOOKUP(B18,[4]考勤分析!$A:$I,7,FALSE) -> 18 | AB18: =VLOOKUP(B18,[4]考勤分析!$A:$I,8,FALSE) -> 5 | AC18: =VLOOKUP(B18,[4]考勤分析!$A:$I,9,FALSE) -> 7 | AD18: 0 | AE18: 1 | AF18: 0 | AG18: 2 | AH18: 0 | AI18: 0 | AK18: =VLOOKUP(B18,[3]总表!$B:$W,22,FALSE) -> 超负荷 | AL18: 2 | AM18: 4 | AN18: 3 | AO18: 2 | AP18: =SUM(AL18:AO18) -> 11 | AQ18: 4-高潜培养对象 | AR18: 揭榜挂帅人选，有实力做专业性对抗； 擅长处理并发任务，工作效率高（从任务完成度和考勤来看）
A19: 17 | B19: 刘燕玲 | C19: 数据治理部 | D19: 标准质量组 | E19: 女 | F19: 10 | G19: 研究生 | H19: 复旦大学 | I19: 组长 | L19: 0 | M19: 数据治理 | N19: 社会招聘 | R19: 24五星质量奖/25行外获奖1 | S19: =VLOOKUP(B19,'[2]62人'!$B:$R,17,FALSE) -> 12 | T19: 0 | U19: 1 | X19: =VLOOKUP(B19,[4]考勤分析!$A:$I,4,FALSE) -> 0.7407286 | Y19: =VLOOKUP(B19,[4]考勤分析!$A:$I,5,FALSE) -> FALSE | Z19: =VLOOKUP(B19,[4]考勤分析!$A:$I,6,FALSE) -> 52 | AA19: =VLOOKUP(B19,[4]考勤分析!$A:$I,7,FALSE) -> 5 | AB19: =VLOOKUP(B19,[4]考勤分析!$A:$I,8,FALSE) -> 3 | AC19: =VLOOKUP(B19,[4]考勤分析!$A:$I,9,FALSE) -> 1 | AD19: 0 | AE19: 0 | AF19: 0 | AG19: 0 | AH19: 0 | AI19: 0 | AK19: =VLOOKUP(B19,[3]总表!$B:$W,22,FALSE) -> #N/A | AL19: 2 | AM19: 2 | AN19: 2 | AO19: 2 | AP19: =SUM(AL19:AO19) -> 8 | AQ19: 2-可培养的二梯队 | AR19: 综合能力都可
A20: 18 | B20: 于璐 | C20: 数据治理部 | D20: 标准质量组 | E20: 女 | F20: 8 | G20: 大学本科 | H20: 合肥工业大学 | I20: 骨干 | J20: 产品经理 | K20: 4 | L20: 1 | M20: 数据治理 | N20: 校园招聘 | R20: 24最佳合作服务奖/24数据文化优秀贡献者 | S20: =VLOOKUP(B20,'[2]62人'!$B:$R,17,FALSE) -> 11 | T20: 2 | U20: 2 | W20: 1 | X20: =VLOOKUP(B20,[4]考勤分析!$A:$I,4,FALSE) -> 0.81636612 | Y20: =VLOOKUP(B20,[4]考勤分析!$A:$I,5,FALSE) -> FALSE | Z20: =VLOOKUP(B20,[4]考勤分析!$A:$I,6,FALSE) -> 42 | AA20: =VLOOKUP(B20,[4]考勤分析!$A:$I,7,FALSE) -> 18 | AB20: =VLOOKUP(B20,[4]考勤分析!$A:$I,8,FALSE) -> 1 | AC20: =VLOOKUP(B20,[4]考勤分析!$A:$I,9,FALSE) -> 0 | AD20: 0 | AE20: 1 | AF20: 0 | AG20: 0 | AH20: 0 | AI20: 0 | AK20: =VLOOKUP(B20,[3]总表!$B:$W,22,FALSE) -> #N/A | AL20: 1 | AM20: 2 | AN20: 2 | AO20: 2 | AP20: =SUM(AL20:AO20) -> 7 | AQ20: 3-不作为优先培养对象 | AR20: 中规中矩
A21: 19 | B21: 米俊文 | C21: 数据治理部 | D21: 架构安全组 | E21: 男 | F21: 16 | G21: 研究生 | H21: 同济大学 | I21: 骨干 | L21: 0 | M21: 架构管理 | N21: 社会招聘 | S21: =VLOOKUP(B21,'[2]62人'!$B:$R,17,FALSE) -> 7 | T21: 1 | V21: 1 | X21: =VLOOKUP(B21,[4]考勤分析!$A:$I,4,FALSE) -> 1.885904 | Y21: =VLOOKUP(B21,[4]考勤分析!$A:$I,5,FALSE) -> TRUE | Z21: =VLOOKUP(B21,[4]考勤分析!$A:$I,6,FALSE) -> 6 | AA21: =VLOOKUP(B21,[4]考勤分析!$A:$I,7,FALSE) -> 32 | AB21: =VLOOKUP(B21,[4]考勤分析!$A:$I,8,FALSE) -> 20 | AC21: =VLOOKUP(B21,[4]考勤分析!$A:$I,9,FALSE) -> 1 | AD21: 0 | AE21: 0 | AF21: 0 | AG21: 0 | AH21: 0 | AI21: 0 | AK21: =VLOOKUP(B21,[3]总表!$B:$W,22,FALSE) -> #N/A | AL21: 1 | AM21: 3 | AN21: 2 | AO21: 2 | AP21: =SUM(AL21:AO21) -> 8 | AQ21: 1.2-专业能力强，但领导力较弱，建议走技术路线 | AR21: 没有管理张力
A22: 20 | B22: 庄家宙 | C22: 数据治理部 | D22: 架构安全组 | E22: 男 | F22: 17 | G22: 大学本科 | H22: 华东师范大学 | I22: 组长 | J22: 产品经理 | K22: 2 | L22: 0 | M22: 数据安全 | N22: 社会招聘 | S22: =VLOOKUP(B22,'[2]62人'!$B:$R,17,FALSE) -> 7 | T22: 3 | X22: =VLOOKUP(B22,[4]考勤分析!$A:$I,4,FALSE) -> 1.3275627 | Y22: =VLOOKUP(B22,[4]考勤分析!$A:$I,5,FALSE) -> TRUE | Z22: =VLOOKUP(B22,[4]考勤分析!$A:$I,6,FALSE) -> 3 | AA22: =VLOOKUP(B22,[4]考勤分析!$A:$I,7,FALSE) -> 59 | AB22: =VLOOKUP(B22,[4]考勤分析!$A:$I,8,FALSE) -> 0 | AC22: =VLOOKUP(B22,[4]考勤分析!$A:$I,9,FALSE) -> 0 | AD22: 0 | AE22: 0 | AF22: 0 | AG22: 0 | AH22: 0 | AI22: 0 | AK22: =VLOOKUP(B22,[3]总表!$B:$W,22,FALSE) -> #N/A | AL22: 2 | AM22: 2 | AN22: 2 | AO22: 2 | AP22: =SUM(AL22:AO22) -> 8 | AQ22: 3-不作为优先培养对象 | AR22: 老古板，缺少新型思维
A23: 21 | B23: 舒宝龙 | C23: 信息管理部 | D23: 分行BP | E23: 男 | F23: 4 | G23: 研究生 | H23: 南方卫理公会大学 | I23: 组长 | L23: 0 | M23: 数据分析 | N23: 社会招聘 | S23: =VLOOKUP(B23,'[2]62人'!$B:$R,17,FALSE) -> 1 | T23: 0 | X23: =VLOOKUP(B23,[4]考勤分析!$A:$I,4,FALSE) -> 0.43922685 | Y23: =VLOOKUP(B23,[4]考勤分析!$A:$I,5,FALSE) -> FALSE | Z23: =VLOOKUP(B23,[4]考勤分析!$A:$I,6,FALSE) -> 49 | AA23: =VLOOKUP(B23,[4]考勤分析!$A:$I,7,FALSE) -> 9 | AB23: =VLOOKUP(B23,[4]考勤分析!$A:$I,8,FALSE) -> 2 | AC23: =VLOOKUP(B23,[4]考勤分析!$A:$I,9,FALSE) -> 0 | AD23: 0 | AE23: 0 | AF23: 0 | AG23: 0 | AH23: 0 | AI23: 0 | AK23: =VLOOKUP(B23,[3]总表!$B:$W,22,FALSE) -> #N/A | AL23: 2 | AM23: 1 | AN23: 1 | AO23: 2 | AP23: =SUM(AL23:AO23) -> 6 | AR23: 双刃剑
A24: 22 | B24: 陆应佳玥 | C24: 信息管理部 | D24: 分行BP | E24: 女 | F24: 3 | G24: 研究生 | H24: 悉尼大学 | L24: 0 | M24: 数据分析 | N24: 校园招聘 | S24: =VLOOKUP(B24,'[2]62人'!$B:$R,17,FALSE) -> 14 | T24: 0 | W24: 2 | X24: =VLOOKUP(B24,[4]考勤分析!$A:$I,4,FALSE) -> 0.34355191 | Y24: =VLOOKUP(B24,[4]考勤分析!$A:$I,5,FALSE) -> FALSE | Z24: =VLOOKUP(B24,[4]考勤分析!$A:$I,6,FALSE) -> 59 | AA24: =VLOOKUP(B24,[4]考勤分析!$A:$I,7,FALSE) -> 0 | AB24: =VLOOKUP(B24,[4]考勤分析!$A:$I,8,FALSE) -> 0 | AC24: =VLOOKUP(B24,[4]考勤分析!$A:$I,9,FALSE) -> 2 | AD24: 0 | AE24: 0 | AF24: 0 | AG24: 0 | AH24: 0 | AI24: 0 | AK24: =VLOOKUP(B24,[3]总表!$B:$W,22,FALSE) -> #N/A | AL24: 1 | AM24: 2 | AN24: 2 | AO24: 2 | AP24: =SUM(AL24:AO24) -> 7 | AQ24: 3-不作为优先培养对象 | AR24: 中规中矩
A25: 23 | B25: 胡承萱 | C25: 信息管理部 | D25: 非零BP | E25: 女 | F25: 4 | G25: 研究生 | H25: 哥伦比亚大学 | I25: 组长 | L25: 0 | M25: 数据分析 | N25: 校园招聘 | S25: =VLOOKUP(B25,'[2]62人'!$B:$R,17,FALSE) -> 15 | T25: 6 | W25: 1 | X25: =VLOOKUP(B25,[4]考勤分析!$A:$I,4,FALSE) -> 2.7296147 | Y25: =VLOOKUP(B25,[4]考勤分析!$A:$I,5,FALSE) -> TRUE | Z25: =VLOOKUP(B25,[4]考勤分析!$A:$I,6,FALSE) -> 7 | AA25: =VLOOKUP(B25,[4]考勤分析!$A:$I,7,FALSE) -> 0 | AB25: =VLOOKUP(B25,[4]考勤分析!$A:$I,8,FALSE) -> 54 | AC25: =VLOOKUP(B25,[4]考勤分析!$A:$I,9,FALSE) -> 1 | AD25: 2 | AE25: 0 | AF25: 0 | AG25: 0 | AH25: 0 | AI25: 0 | AK25: =VLOOKUP(B25,[3]总表!$B:$W,22,FALSE) -> #N/A | AL25: 2 | AM25: 3 | AN25: 3 | AO25: 3 | AP25: =SUM(AL25:AO25) -> 11 | AQ25: 1.1-专业能力强，但领导力较弱 | AR25: 有冲劲
A26: 24 | B26: 王亮 | C26: 信息管理部 | D26: 非零BP | E26: 男 | F26: 6 | G26: 研究生 | H26: 上海大学 | I26: 骨干 | L26: 0 | M26: 数据分析 | N26: 校园招聘 | S26: =VLOOKUP(B26,'[2]62人'!$B:$R,17,FALSE) -> 10 | T26: 0 | X26: =VLOOKUP(B26,[4]考勤分析!$A:$I,4,FALSE) -> #N/A | Y26: =VLOOKUP(B26,[4]考勤分析!$A:$I,5,FALSE) -> #N/A | Z26: =VLOOKUP(B26,[4]考勤分析!$A:$I,6,FALSE) -> #N/A | AA26: =VLOOKUP(B26,[4]考勤分析!$A:$I,7,FALSE) -> #N/A | AB26: =VLOOKUP(B26,[4]考勤分析!$A:$I,8,FALSE) -> #N/A | AC26: =VLOOKUP(B26,[4]考勤分析!$A:$I,9,FALSE) -> #N/A | AD26: 0 | AE26: 0 | AF26: 0 | AG26: 0 | AH26: 0 | AI26: 0 | AK26: =VLOOKUP(B26,[3]总表!$B:$W,22,FALSE) -> #N/A | AL26: 1 | AM26: 2 | AN26: 2 | AO26: 2 | AP26: =SUM(AL26:AO26) -> 7 | AQ26: 3-不作为优先培养对象 | AR26: 一般
A27: 25 | B27: 曹婉茹 | C27: 信息管理部 | D27: 零售BP | E27: 女 | F27: 6 | G27: 研究生 | H27: 北京师范大学 | I27: 组长 | L27: 0 | M27: 数据分析 | N27: 校园招聘 | O27: 第三党支部组织委员 | S27: =VLOOKUP(B27,'[2]62人'!$B:$R,17,FALSE) -> 8 | T27: 0 | X27: =VLOOKUP(B27,[4]考勤分析!$A:$I,4,FALSE) -> 1.2239253 | Y27: =VLOOKUP(B27,[4]考勤分析!$A:$I,5,FALSE) -> FALSE | Z27: =VLOOKUP(B27,[4]考勤分析!$A:$I,6,FALSE) -> 30 | AA27: =VLOOKUP(B27,[4]考勤分析!$A:$I,7,FALSE) -> 17 | AB27: =VLOOKUP(B27,[4]考勤分析!$A:$I,8,FALSE) -> 12 | AC27: =VLOOKUP(B27,[4]考勤分析!$A:$I,9,FALSE) -> 2 | AD27: 1 | AE27: 7 | AF27: 0 | AG27: 0 | AH27: 0 | AI27: 0 | AK27: =VLOOKUP(B27,[3]总表!$B:$W,22,FALSE) -> #N/A | AL27: 2 | AM27: 2 | AN27: 2 | AO27: 2 | AP27: =SUM(AL27:AO27) -> 8 | AQ27: 2-可培养的二梯队 | AR27: 内敛，综合能力可以
A28: 26 | B28: 杨陆 | C28: 信息管理部 | D28: 零售BP | E28: 女 | F28: 4 | G28: 研究生 | H28: 南京师范大学 | I28: 骨干 | J28: 产品经理 | K28: 2 | L28: 0 | M28: 数据分析 | N28: 校园招聘 | P28: 工会会员代表 | S28: =VLOOKUP(B28,'[2]62人'!$B:$R,17,FALSE) -> 6 | T28: 0 | X28: =VLOOKUP(B28,[4]考勤分析!$A:$I,4,FALSE) -> 0.92281019 | Y28: =VLOOKUP(B28,[4]考勤分析!$A:$I,5,FALSE) -> FALSE | Z28: =VLOOKUP(B28,[4]考勤分析!$A:$I,6,FALSE) -> 41 | AA28: =VLOOKUP(B28,[4]考勤分析!$A:$I,7,FALSE) -> 15 | AB28: =VLOOKUP(B28,[4]考勤分析!$A:$I,8,FALSE) -> 3 | AC28: =VLOOKUP(B28,[4]考勤分析!$A:$I,9,FALSE) -> 1 | AD28: 0 | AE28: 0 | AF28: 0 | AG28: 0 | AH28: 0 | AI28: 0 | AK28: =VLOOKUP(B28,[3]总表!$B:$W,22,FALSE) -> #N/A | AL28: 2 | AM28: 2 | AN28: 2 | AO28: 2 | AP28: =SUM(AL28:AO28) -> 8 | AQ28: 2-可培养的二梯队 | AR28: 偏外向，敢表达
A29: 27 | B29: 郭庆睿 | C29: 信息统计部 | D29: 管理信息组 | E29: 男 | F29: 8 | G29: 研究生 | H29: 复旦大学 | I29: 组长 | L29: 2 | M29: 数据分析 | N29: 校园招聘 | S29: =VLOOKUP(B29,'[2]62人'!$B:$R,17,FALSE) -> 8 | T29: 3 | X29: =VLOOKUP(B29,[4]考勤分析!$A:$I,4,FALSE) -> 3.0276953 | Y29: =VLOOKUP(B29,[4]考勤分析!$A:$I,5,FALSE) -> TRUE | Z29: =VLOOKUP(B29,[4]考勤分析!$A:$I,6,FALSE) -> 9 | AA29: =VLOOKUP(B29,[4]考勤分析!$A:$I,7,FALSE) -> 3 | AB29: =VLOOKUP(B29,[4]考勤分析!$A:$I,8,FALSE) -> 36 | AC29: =VLOOKUP(B29,[4]考勤分析!$A:$I,9,FALSE) -> 16 | AD29: 0 | AE29: 0 | AF29: 0 | AG29: 0 | AH29: 0 | AI29: 0 | AK29: =VLOOKUP(B29,[3]总表!$B:$W,22,FALSE) -> #N/A | AL29: 2 | AM29: 3 | AN29: 3 | AO29: 3 | AP29: =SUM(AL29:AO29) -> 11 | AQ29: 1.1-专业能力强，但领导力较弱 | AR29: 有良好的大局观
A30: 28 | B30: 王素雅 | C30: 信息统计部 | D30: 管理信息组 | E30: 女 | F30: 6 | G30: 研究生 | H30: 华中师范大学 | I30: 骨干 | J30: 产品经理 | K30: 4 | L30: 1 | M30: 数据分析 | N30: 校园招聘 | S30: =VLOOKUP(B30,'[2]62人'!$B:$R,17,FALSE) -> 10 | T30: 0 | W30: 1 | X30: =VLOOKUP(B30,[4]考勤分析!$A:$I,4,FALSE) -> 1.9007213 | Y30: =VLOOKUP(B30,[4]考勤分析!$A:$I,5,FALSE) -> TRUE | Z30: =VLOOKUP(B30,[4]考勤分析!$A:$I,6,FALSE) -> 19 | AA30: =VLOOKUP(B30,[4]考勤分析!$A:$I,7,FALSE) -> 17 | AB30: =VLOOKUP(B30,[4]考勤分析!$A:$I,8,FALSE) -> 21 | AC30: =VLOOKUP(B30,[4]考勤分析!$A:$I,9,FALSE) -> 5 | AD30: 0 | AE30: 1 | AF30: 0 | AG30: 0 | AH30: 0 | AI30: 0 | AK30: =VLOOKUP(B30,[3]总表!$B:$W,22,FALSE) -> #N/A | AL30: 1 | AM30: 2 | AN30: 2 | AO30: 3 | AP30: =SUM(AL30:AO30) -> 8 | AQ30: 3-不作为优先培养对象 | AR30: 有冲劲，当前偏个人发展型
A31: 29 | B31: 张伟亮 | C31: 信息统计部 | D31: 监管数据治理 | E31: 男 | F31: 7 | G31: 研究生 | H31: 西南交通大学 | I31: 组长 | J31: 产品经理 | K31: 2 | L31: 1 | M31: 监管统计 | N31: 校园招聘 | S31: =VLOOKUP(B31,'[2]62人'!$B:$R,17,FALSE) -> 11 | T31: 4 | X31: =VLOOKUP(B31,[4]考勤分析!$A:$I,4,FALSE) -> 3.347878 | Y31: =VLOOKUP(B31,[4]考勤分析!$A:$I,5,FALSE) -> TRUE | Z31: =VLOOKUP(B31,[4]考勤分析!$A:$I,6,FALSE) -> 5 | AA31: =VLOOKUP(B31,[4]考勤分析!$A:$I,7,FALSE) -> 3 | AB31: =VLOOKUP(B31,[4]考勤分析!$A:$I,8,FALSE) -> 35 | AC31: =VLOOKUP(B31,[4]考勤分析!$A:$I,9,FALSE) -> 18 | AD31: 0 | AE31: 0 | AF31: 0 | AG31: 0 | AH31: 0 | AI31: 0 | AK31: =VLOOKUP(B31,[3]总表!$B:$W,22,FALSE) -> #N/A | AL31: 2 | AM31: 3 | AN31: 3 | AO31: 2 | AP31: =SUM(AL31:AO31) -> 10 | AQ31: 1.1-专业能力强，但领导力较弱 | AR31: 渴望被提拔，有进取心，需要转型引导
A32: 30 | B32: 王书祥 | C32: 信息统计部 | D32: 监管数据治理 | E32: 男 | F32: 11 | G32: 大学本科 | H32: 上海对外经贸大学 | I32: 骨干 | J32: 产品经理 | K32: 1 | L32: 0 | M32: 监管统计 | N32: 社会招聘 | S32: =VLOOKUP(B32,'[2]62人'!$B:$R,17,FALSE) -> 10 | T32: 0 | X32: =VLOOKUP(B32,[4]考勤分析!$A:$I,4,FALSE) -> 1.8831713 | Y32: =VLOOKUP(B32,[4]考勤分析!$A:$I,5,FALSE) -> TRUE | Z32: =VLOOKUP(B32,[4]考勤分析!$A:$I,6,FALSE) -> 13 | AA32: =VLOOKUP(B32,[4]考勤分析!$A:$I,7,FALSE) -> 15 | AB32: =VLOOKUP(B32,[4]考勤分析!$A:$I,8,FALSE) -> 31 | AC32: =VLOOKUP(B32,[4]考勤分析!$A:$I,9,FALSE) -> 1 | AD32: 0 | AE32: 0 | AF32: 0 | AG32: 0 | AH32: 0 | AI32: 0 | AK32: =VLOOKUP(B32,[3]总表!$B:$W,22,FALSE) -> #N/A | AL32: 1 | AM32: 2 | AN32: 2 | AO32: 2 | AP32: =SUM(AL32:AO32) -> 7 | AQ32: 3-不作为优先培养对象 | AR32: 中规中矩
A33: 31 | B33: 王新 | C33: 信息统计部 | D33: 监管统计组 | E33: 男 | F33: 9 | G33: 大学本科 | H33: 吉林大学 | I33: 组长 | J33: 产品经理 | K33: 2 | L33: 0 | M33: 数据分析 | N33: 社会招聘 | S33: =VLOOKUP(B33,'[2]62人'!$B:$R,17,FALSE) -> 14 | T33: 19 | X33: =VLOOKUP(B33,[4]考勤分析!$A:$I,4,FALSE) -> 1.6084409 | Y33: =VLOOKUP(B33,[4]考勤分析!$A:$I,5,FALSE) -> FALSE | Z33: =VLOOKUP(B33,[4]考勤分析!$A:$I,6,FALSE) -> 23 | AA33: =VLOOKUP(B33,[4]考勤分析!$A:$I,7,FALSE) -> 23 | AB33: =VLOOKUP(B33,[4]考勤分析!$A:$I,8,FALSE) -> 8 | AC33: =VLOOKUP(B33,[4]考勤分析!$A:$I,9,FALSE) -> 8 | AD33: 0 | AE33: 0 | AF33: 0 | AG33: 0 | AH33: 0 | AI33: 0 | AK33: =VLOOKUP(B33,[3]总表!$B:$W,22,FALSE) -> #N/A | AL33: 1 | AM33: 3 | AN33: 2 | AO33: 2 | AP33: =SUM(AL33:AO33) -> 8 | AQ33: 1.1-专业能力强，但领导力较弱 | AR33: 欠缺管理张力
A34: 32 | B34: 杨婧 | C34: 智能创新部 | D34: AI产品运营组 | E34: 女 | F34: 5 | G34: 研究生 | H34: 中国科学技术大学 | I34: 组长 | J34: 产品经理 | K34: 1 | L34: 0 | M34: 数据研发 | N34: 校园招聘 | R34: 23/24数据文化优秀贡献者/24研究与创新奖 | S34: =VLOOKUP(B34,'[2]62人'!$B:$R,17,FALSE) -> 14 | T34: 0 | W34: 3 | X34: =VLOOKUP(B34,[4]考勤分析!$A:$I,4,FALSE) -> 2.7654645 | Y34: =VLOOKUP(B34,[4]考勤分析!$A:$I,5,FALSE) -> TRUE | Z34: =VLOOKUP(B34,[4]考勤分析!$A:$I,6,FALSE) -> 9 | AA34: =VLOOKUP(B34,[4]考勤分析!$A:$I,7,FALSE) -> 14 | AB34: =VLOOKUP(B34,[4]考勤分析!$A:$I,8,FALSE) -> 20 | AC34: =VLOOKUP(B34,[4]考勤分析!$A:$I,9,FALSE) -> 18 | AD34: 0 | AE34: 1 | AF34: 1 | AG34: 2 | AH34: 0 | AI34: 0 | AK34: =VLOOKUP(B34,[3]总表!$B:$W,22,FALSE) -> 超负荷 | AL34: 1 | AM34: 3 | AN34: 3 | AO34: 2 | AP34: =SUM(AL34:AO34) -> 9 | AQ34: 1.1-专业能力强，但领导力较弱 | AR34: 有培养潜力，因年限较短缺乏更深入的思考，需要引导
A35: 33 | B35: 邱玥 | C35: 智能创新部 | D35: AI产品运营组 | E35: 女 | F35: 3 | G35: 研究生 | H35: 东华大学 | I35: 骨干 | L35: 0 | M35: 数据研发 | N35: 校园招聘 | S35: =VLOOKUP(B35,'[2]62人'!$B:$R,17,FALSE) -> 16 | T35: 0 | W35: 1 | X35: =VLOOKUP(B35,[4]考勤分析!$A:$I,4,FALSE) -> 1.4472996 | Y35: =VLOOKUP(B35,[4]考勤分析!$A:$I,5,FALSE) -> FALSE | Z35: =VLOOKUP(B35,[4]考勤分析!$A:$I,6,FALSE) -> 14 | AA35: =VLOOKUP(B35,[4]考勤分析!$A:$I,7,FALSE) -> 39 | AB35: =VLOOKUP(B35,[4]考勤分析!$A:$I,8,FALSE) -> 7 | AC35: =VLOOKUP(B35,[4]考勤分析!$A:$I,9,FALSE) -> 1 | AD35: 1 | AE35: 1 | AF35: 1 | AG35: 2 | AH35: 2 | AI35: 4 | AK35: =VLOOKUP(B35,[3]总表!$B:$W,22,FALSE) -> 适中 | AL35: 1 | AM35: 2 | AN35: 2 | AO35: 2 | AP35: =SUM(AL35:AO35) -> 7 | AQ35: 3-不作为优先培养对象 | AR35: 中规中矩、内敛
A36: 3 | B36: 李响 | C36: 智能创新部 | D36: AI基础研发组 | E36: 男 | F36: 13 | G36: 大学本科 | H36: 哈尔滨工业大学 | I36: 组长 | J36: 架构师 | K36: 5 | L36: 1 | M36: 数据研发 | N36: 社会招聘 | S36: =VLOOKUP(B36,'[2]62人'!$B:$R,17,FALSE) -> 7 | T36: 1 | U36: 1 | W36: 2 | X36: =VLOOKUP(B36,[4]考勤分析!$A:$I,4,FALSE) -> 1.297161 | Y36: =VLOOKUP(B36,[4]考勤分析!$A:$I,5,FALSE) -> FALSE | Z36: =VLOOKUP(B36,[4]考勤分析!$A:$I,6,FALSE) -> 35 | AA36: =VLOOKUP(B36,[4]考勤分析!$A:$I,7,FALSE) -> 16 | AB36: =VLOOKUP(B36,[4]考勤分析!$A:$I,8,FALSE) -> 5 | AC36: =VLOOKUP(B36,[4]考勤分析!$A:$I,9,FALSE) -> 3 | AD36: 2 | AE36: 0 | AF36: 2 | AG36: 5 | AH36: 16 | AI36: 13 | AK36: =VLOOKUP(B36,[3]总表!$B:$W,22,FALSE) -> 超负荷 | AL36: 1 | AM36: 4 | AN36: 2 | AO36: 2 | AP36: =SUM(AL36:AO36) -> 9 | AQ36: 1.1-专业能力强，但领导力较弱 | AR36: 技术型
A37: 35 | B37: 于中宝 | C37: 智能创新部 | D37: AI基础研发组 | E37: 男 | F37: 6 | G37: 研究生 | H37: 华东理工大学 | I37: 骨干 | J37: 架构师 | K37: 6 | L37: 0 | M37: 数据研发 | N37: 校园招聘 | R37: 23数据文化优秀贡献者/24年度宣传大使 | S37: =VLOOKUP(B37,'[2]62人'!$B:$R,17,FALSE) -> 12 | T37: 4 | W37: 2 | X37: =VLOOKUP(B37,[4]考勤分析!$A:$I,4,FALSE) -> 1.9853808 | Y37: =VLOOKUP(B37,[4]考勤分析!$A:$I,5,FALSE) -> FALSE | Z37: =VLOOKUP(B37,[4]考勤分析!$A:$I,6,FALSE) -> 9 | AA37: =VLOOKUP(B37,[4]考勤分析!$A:$I,7,FALSE) -> 34 | AB37: =VLOOKUP(B37,[4]考勤分析!$A:$I,8,FALSE) -> 12 | AC37: =VLOOKUP(B37,[4]考勤分析!$A:$I,9,FALSE) -> 7 | AD37: 2 | AE37: 2 | AF37: 1 | AG37: 3 | AH37: 9 | AI37: 5 | AK37: =VLOOKUP(B37,[3]总表!$B:$W,22,FALSE) -> 超负荷 | AL37: 2 | AM37: 2 | AN37: 2 | AO37: 3 | AP37: =SUM(AL37:AO37) -> 9 | AQ37: 2-可培养的二梯队 | AR37: 有落差感，需要正确引导培养
A38: 36 | B38: 杨萍 | C38: 综合管理部 | D38: 测试管理组 | E38: 女 | F38: 11 | G38: 研究生 | H38: 上海大学 | I38: 组长 | L38: 1 | M38: 数据测试 | N38: 社会招聘 | S38: =VLOOKUP(B38,'[2]62人'!$B:$R,17,FALSE) -> 11 | T38: 0 | X38: =VLOOKUP(B38,[4]考勤分析!$A:$I,4,FALSE) -> 3.1222595 | Y38: =VLOOKUP(B38,[4]考勤分析!$A:$I,5,FALSE) -> TRUE | Z38: =VLOOKUP(B38,[4]考勤分析!$A:$I,6,FALSE) -> 5 | AA38: =VLOOKUP(B38,[4]考勤分析!$A:$I,7,FALSE) -> 13 | AB38: =VLOOKUP(B38,[4]考勤分析!$A:$I,8,FALSE) -> 31 | AC38: =VLOOKUP(B38,[4]考勤分析!$A:$I,9,FALSE) -> 18 | AD38: 0 | AE38: 0 | AF38: 0 | AG38: 0 | AH38: 0 | AI38: 0 | AK38: =VLOOKUP(B38,[3]总表!$B:$W,22,FALSE) -> #N/A | AL38: 3 | AM38: 4 | AN38: 3 | AO38: 3 | AP38: =SUM(AL38:AO38) -> 13 | AQ38: 4-高潜培养对象 | AR38: 可以考虑轮岗
A39: 37 | B39: 蒋书润 | C39: 综合管理部 | D39: 测试管理组 | E39: 女 | F39: 3 | G39: 研究生 | H39: 南加州大学 | L39: 0 | M39: 数据测试 | N39: 校园招聘 | R39: 24最佳新人 | S39: =VLOOKUP(B39,'[2]62人'!$B:$R,17,FALSE) -> 13 | T39: 11 | X39: =VLOOKUP(B39,[4]考勤分析!$A:$I,4,FALSE) -> 1.4125941 | Y39: =VLOOKUP(B39,[4]考勤分析!$A:$I,5,FALSE) -> FALSE | Z39: =VLOOKUP(B39,[4]考勤分析!$A:$I,6,FALSE) -> 26 | AA39: =VLOOKUP(B39,[4]考勤分析!$A:$I,7,FALSE) -> 22 | AB39: =VLOOKUP(B39,[4]考勤分析!$A:$I,8,FALSE) -> 13 | AC39: =VLOOKUP(B39,[4]考勤分析!$A:$I,9,FALSE) -> 1 | AD39: 0 | AE39: 0 | AF39: 0 | AG39: 0 | AH39: 0 | AI39: 0 | AK39: =VLOOKUP(B39,[3]总表!$B:$W,22,FALSE) -> #N/A | AL39: 2 | AM39: 2 | AN39: 3 | AO39: 3 | AP39: =SUM(AL39:AO39) -> 10 | AQ39: 4-高潜培养对象 | AR39: 有魄力，有担当，有潜在的管理张力
A40: 38 | B40: 黄佳佳 | C40: 综合管理部 | D40: 项目管理团队 | E40: 男 | F40: 7 | G40: 研究生 | H40: 东华大学 | I40: 骨干 | L40: 1 | M40: 项目管理 | N40: 校园招聘 | O40: 第三党支部纪检委员 | S40: =VLOOKUP(B40,'[2]62人'!$B:$R,17,FALSE) -> 15 | T40: 5 | X40: =VLOOKUP(B40,[4]考勤分析!$A:$I,4,FALSE) -> 3.0750231 | Y40: =VLOOKUP(B40,[4]考勤分析!$A:$I,5,FALSE) -> TRUE | Z40: =VLOOKUP(B40,[4]考勤分析!$A:$I,6,FALSE) -> 4 | AA40: =VLOOKUP(B40,[4]考勤分析!$A:$I,7,FALSE) -> 11 | AB40: =VLOOKUP(B40,[4]考勤分析!$A:$I,8,FALSE) -> 29 | AC40: =VLOOKUP(B40,[4]考勤分析!$A:$I,9,FALSE) -> 16 | AD40: 3 | AE40: 0 | AF40: 0 | AG40: 0 | AH40: 0 | AI40: 0 | AK40: =VLOOKUP(B40,[3]总表!$B:$W,22,FALSE) -> #N/A | AL40: 2 | AM40: 2 | AN40: 2 | AO40: 2 | AP40: =SUM(AL40:AO40) -> 8 | AQ40: 3-不作为优先培养对象 | AR40: 老黄牛型，需要突破
...

Sheet 2.2 工作负荷分析-开发类岗位
A1: 序号 | B1: 姓名 | C1: 基本信息 | J1: 工作饱和度量化 | W1: 饱和度量化 不饱和：平均加班时长1h以下/无变更任务无主管应用非组长骨干/科长评定不饱和 超负荷：季度变更任务≥10/加班4H以上超过30次/平均加班时长3H以上/科长评定超负荷 | X1: 工作内容 | AE1: 岗职适配程度
C2: 团队 | D2: 组 | E2: 性别 | F2: 累计工龄 | G2: 最高学历 | H2: 最高学历毕业院校 | I2: 组长/骨干标识 | J2: 平均加班时长 | K2: 工作时长高于部门均值 | L2: 1h以下 | M2: 加班1-2h频次 | N2: 加班2-4h频次 | O2: 加班4h以上频次 | P2: 牵头项目数量 | Q2: 牵头需求数量 | R2: 主管应用系统数量（近六个月有变更的数量） | S2: 新paso体系参与应用数量 | T2: 二季度变更任务数 | U2: 三季度变更任务数 | V2: 截止三季度扣分事件或缺陷 | X2: 当前重点工作项（前期已收集） | Y2: 当前P0级工作任务（主要投入的工程/项目/研发系统） | Z2: P0级工作投入占比 | AA2: 当前P1级工作任务（次要工作任务） | AB2: P1级工作投入占比 | AC2: 其余工作任务（如无可不填） | AD2: 如该员工休假，B角人员是谁（如无请填写无） | AE2: 任务难度与人员职级、技能匹配程度 任务难度远高/远低于个人能力 任务难度略高/略低于个人能力 基本适配 | AF2: 个人状态 不饱和 适中 超负荷
A3: 1 | B3: 黄哲睿 | C3: 数据开发部 | D3: 模型设计组 | E3: 男 | F3: 7 | G3: 大学本科 | H3: 南京大学 | I3: 组长 | J3: =VLOOKUP(B3,[3]加班情况分析!D:G,4,FALSE) -> 3.9553763 | K3: =VLOOKUP(B3,[3]加班情况分析!D:H,5,FALSE) -> TRUE | L3: =VLOOKUP(B3,[3]加班情况分析!D:L,6,FALSE) -> 8 | M3: =VLOOKUP($B3,[3]加班情况分析!$D:$L,7,FALSE) -> 2 | N3: =VLOOKUP($B3,[3]加班情况分析!$D:$L,8,FALSE) -> 12 | O3: =VLOOKUP(B3,[3]加班情况分析!D:L,9,FALSE) -> 40 | Q3: =VLOOKUP(B3,'[3]牵头需求（当前进行中）'!A:B,2,FALSE) -> 1 | S3: 1 | W3: 超负荷 | X3: 智芯工程牵头、数据架构（数据模型） | Y3: 组长，牵头模型组建立、数据架构数仓部分工作，智芯工作收尾 | Z3: 0.5 | AA3: 研究数据仓库肩负暨整体切换整合模型方案 | AB3: 0.5 | AE3: 任务难度略高/略低于个人能力 | AF3: 适中
A4: 2 | B4: 陆慧 | C4: 数据开发部 | D4: 模型设计组 | E4: 女 | F4: 13 | G4: 研究生 | H4: 南京大学 | I4: 骨干 | J4: =VLOOKUP(B4,[3]加班情况分析!D:G,4,FALSE) -> 2.7979837 | K4: =VLOOKUP(B4,[3]加班情况分析!D:H,5,FALSE) -> TRUE | L4: =VLOOKUP(B4,[3]加班情况分析!D:L,6,FALSE) -> 10 | M4: =VLOOKUP($B4,[3]加班情况分析!$D:$L,7,FALSE) -> 4 | N4: =VLOOKUP($B4,[3]加班情况分析!$D:$L,8,FALSE) -> 32 | O4: =VLOOKUP(B4,[3]加班情况分析!D:L,9,FALSE) -> 12 | S4: 1 | W4: 适中 | X4: 智芯工程整合模型（核心存款）、公共领域模型设计 | Y4: 牵头具体模型设计工作，参与整体切换方案、整合模型规范制定等工作 | Z4: 0.8 | AA4: 智芯整合模型收尾 | AB4: 0.2 | AE4: 基本适配 | AF4: 适中
A5: 3 | B5: 罗仁杰 | C5: 数据开发部 | D5: 需求接入组 | E5: 男 | F5: 20 | G5: 大学本科 | H5: 兰州理工大学 | I5: 组长 | J5: =VLOOKUP(B5,[3]加班情况分析!D:G,4,FALSE) -> 2.8332375 | K5: =VLOOKUP(B5,[3]加班情况分析!D:H,5,FALSE) -> TRUE | L5: =VLOOKUP(B5,[3]加班情况分析!D:L,6,FALSE) -> 3 | M5: =VLOOKUP($B5,[3]加班情况分析!$D:$L,7,FALSE) -> 10 | N5: =VLOOKUP($B5,[3]加班情况分析!$D:$L,8,FALSE) -> 38 | O5: =VLOOKUP(B5,[3]加班情况分析!D:L,9,FALSE) -> 7 | Q5: =VLOOKUP(B5,'[3]牵头需求（当前进行中）'!A:B,2,FALSE) -> 5 | R5: =VLOOKUP(B5,[3]主管应用系统数量!I:J,2,FALSE) -> 1 | S5: 1 | T5: =VLOOKUP(B5,[3]二季度变更任务!A:B,2,FALSE) -> 24 | U5: =VLOOKUP(B5,[3]三季度变更任务!A:B,2,FALSE) -> 13 | W5: 超负荷 | X5: 批量治理，批量运营，采集平台推广 | Y5: 牵头数据接入组工作，批量治理，批量运营，采集平台推广 | Z5: 0.7 | AA5: 采集平台推广，各类配合改造项目需求入仓工作 | AB5: 0.3 | AE5: 任务难度略高/略低于个人能力 | AF5: 适中
A6: 4 | B6: 李卓辉 | C6: 数据开发部 | D6: 需求接入组 | E6: 男 | F6: 18 | G6: 研究生 | H6: 华东师范大学 | I6: 骨干候选人 | J6: =VLOOKUP(B6,[3]加班情况分析!D:G,4,FALSE) -> 2.4295151 | K6: =VLOOKUP(B6,[3]加班情况分析!D:H,5,FALSE) -> FALSE | L6: =VLOOKUP(B6,[3]加班情况分析!D:L,6,FALSE) -> 0 | M6: =VLOOKUP($B6,[3]加班情况分析!$D:$L,7,FALSE) -> 10 | N6: =VLOOKUP($B6,[3]加班情况分析!$D:$L,8,FALSE) -> 49 | O6: =VLOOKUP(B6,[3]加班情况分析!D:L,9,FALSE) -> 0 | S6: 1 | U6: =VLOOKUP(B6,[3]三季度变更任务!A:B,2,FALSE) -> 1 | W6: 不饱和 | X6: 一表通衍生区应用 | Y6: 一表通衍生区，配合罗仁杰数据治理 | Z6: 1 | AE6: 任务难度略高/略低于个人能力 | AF6: 不饱和
A7: 5 | B7: 兰昕蕾 | C7: 数据开发部 | D7: 数仓开发组 | E7: 女 | F7: 4 | G7: 研究生 | H7: 华东师范大学 | I7: 组长 | J7: =VLOOKUP(B7,[3]加班情况分析!D:G,4,FALSE) -> 3.6498497 | K7: =VLOOKUP(B7,[3]加班情况分析!D:H,5,FALSE) -> TRUE | L7: =VLOOKUP(B7,[3]加班情况分析!D:L,6,FALSE) -> 3 | M7: =VLOOKUP($B7,[3]加班情况分析!$D:$L,7,FALSE) -> 4 | N7: =VLOOKUP($B7,[3]加班情况分析!$D:$L,8,FALSE) -> 24 | O7: =VLOOKUP(B7,[3]加班情况分析!D:L,9,FALSE) -> 30 | Q7: =VLOOKUP(B7,'[3]牵头需求（当前进行中）'!A:B,2,FALSE) -> 2 | S7: 1 | T7: =VLOOKUP(B7,[3]二季度变更任务!A:B,2,FALSE) -> 8 | U7: =VLOOKUP(B7,[3]三季度变更任务!A:B,2,FALSE) -> 7 | W7: 超负荷 | X7: 智芯工程、渠道集市、特征集市、图谱集市 | Y7: 组长牵头数仓开发组工作 | Z7: 0.5 | AA7: 对数据仓库开发工艺流程dataops、开发规范、减负等工作具体落地 | AB7: 0.5 | AE7: 任务难度略高/略低于个人能力 | AF7: 适中
A8: 6 | B8: 邹小芳 | C8: 数据开发部 | D8: 数仓开发组 | E8: 女 | F8: 11 | G8: 大学本科 | H8: 江西财经大学 | I8: 组长 | J8: =VLOOKUP(B8,[3]加班情况分析!D:G,4,FALSE) -> 2.6259748 | K8: =VLOOKUP(B8,[3]加班情况分析!D:H,5,FALSE) -> TRUE | L8: =VLOOKUP(B8,[3]加班情况分析!D:L,6,FALSE) -> 5 | M8: =VLOOKUP($B8,[3]加班情况分析!$D:$L,7,FALSE) -> 13 | N8: =VLOOKUP($B8,[3]加班情况分析!$D:$L,8,FALSE) -> 27 | O8: =VLOOKUP(B8,[3]加班情况分析!D:L,9,FALSE) -> 8 | Q8: =VLOOKUP(B8,'[3]牵头需求（当前进行中）'!A:B,2,FALSE) -> 2 | S8: 2 | W8: 超负荷 | X8: 征信牵头人 | Y8: 组长，数据应用组牵头人，征信牵头人 | Z8: 1 | AE8: 任务难度略高/略低于个人能力 | AF8: 超负荷
A9: 7 | B9: 丁晨 | C9: 数据开发部 | D9: 数仓开发组 | E9: 男 | F9: 3 | G9: 研究生 | H9: 南京信息工程大学 | I9: 组长 | J9: =VLOOKUP(B9,[3]加班情况分析!D:G,4,FALSE) -> 3.8709426 | K9: =VLOOKUP(B9,[3]加班情况分析!D:H,5,FALSE) -> TRUE | L9: =VLOOKUP(B9,[3]加班情况分析!D:L,6,FALSE) -> 1 | M9: =VLOOKUP($B9,[3]加班情况分析!$D:$L,7,FALSE) -> 4 | N9: =VLOOKUP($B9,[3]加班情况分析!$D:$L,8,FALSE) -> 23 | O9: =VLOOKUP(B9,[3]加班情况分析!D:L,9,FALSE) -> 33 | Q9: =VLOOKUP(B9,'[3]牵头需求（当前进行中）'!A:B,2,FALSE) -> 2 | R9: =VLOOKUP(B9,[3]主管应用系统数量!I:J,2,FALSE) -> 1 | S9: 3 | T9: =VLOOKUP(B9,[3]二季度变更任务!A:B,2,FALSE) -> 10 | U9: =VLOOKUP(B9,[3]三季度变更任务!A:B,2,FALSE) -> 6 | W9: 超负荷 | X9: 智芯工程、整合模型（核心公共）、金融市场集市 | Y9: 组长，拟纳入数据应用组，与邹小芳搭配 | Z9: 0.5 | AA9: 牵头机构改造工作 | AB9: 0.5 | AE9: 任务难度略高/略低于个人能力 | AF9: 适中
A10: 8 | B10: 康冉 | C10: 数据开发部 | D10: 项目管理团队 | E10: 女 | F10: =VLOOKUP(B10,[1]累计工龄!A:B,2,FALSE) -> 5 | G10: 研究生 | H10: 南京师范大学 | I10: 骨干 | J10: =VLOOKUP(B10,[3]加班情况分析!D:G,4,FALSE) -> 2.3188715 | K10: =VLOOKUP(B10,[3]加班情况分析!D:H,5,FALSE) -> FALSE | L10: =VLOOKUP(B10,[3]加班情况分析!D:L,6,FALSE) -> 11 | M10: =VLOOKUP($B10,[3]加班情况分析!$D:$L,7,FALSE) -> 7 | N10: =VLOOKUP($B10,[3]加班情况分析!$D:$L,8,FALSE) -> 24 | O10: =VLOOKUP(B10,[3]加班情况分析!D:L,9,FALSE) -> 6 | P10: =VLOOKUP(B10,'[3]牵头项目（当前进行中）'!A:B,2,FALSE) -> 3 | Q10: =VLOOKUP(B10,'[3]牵头需求（当前进行中）'!A:B,2,FALSE) -> 15 | R10: =VLOOKUP(B10,[3]主管应用系统数量!I:J,2,FALSE) -> 1 | S10: 1 | U10: =VLOOKUP(B10,[3]三季度变更任务!A:B,2,FALSE) -> 10 | W10: 超负荷 | Y10: 1104报送 | Z10: 1 | AE10: 基本适配 | AF10: 适中
A11: 67 | B11: 钱磊 | C11: 数据开发部 | D11: 应用开发组/监管报送 | E11: 男 | F11: 9 | G11: 大学本科 | H11: 海南大学 | I11: / | J11: =VLOOKUP(B11,[3]加班情况分析!D:G,4,FALSE) -> 4.0337366 | K11: =VLOOKUP(B11,[3]加班情况分析!D:H,5,FALSE) -> TRUE | L11: =VLOOKUP(B11,[3]加班情况分析!D:L,6,FALSE) -> 1 | M11: =VLOOKUP($B11,[3]加班情况分析!$D:$L,7,FALSE) -> 6 | N11: =VLOOKUP($B11,[3]加班情况分析!$D:$L,8,FALSE) -> 23 | O11: =VLOOKUP(B11,[3]加班情况分析!D:L,9,FALSE) -> 32 | P11: =VLOOKUP(B11,'[3]牵头项目（当前进行中）'!A:B,2,FALSE) -> 1 | Q11: =VLOOKUP(B11,'[3]牵头需求（当前进行中）'!A:B,2,FALSE) -> 7 | R11: =VLOOKUP(B11,[3]主管应用系统数量!I:J,2,FALSE) -> 1 | S11: 1 | T11: =VLOOKUP(B11,[3]二季度变更任务!A:B,2,FALSE) -> 1 | U11: =VLOOKUP(B11,[3]三季度变更任务!A:B,2,FALSE) -> 8 | W11: 超负荷 | X11: 新线监管组件、大集中、FAL | Y11: 新线监管组件、大集中、FAL | Z11: 1 | AE11: 基本适配 | AF11: 超负荷
A12: 10 | B12: 史朋飞 | C12: 数据平台部 | D12: 运维支持组 | E12: 男 | F12: 12 | G12: 大学本科 | H12: 河南理工大学 | I12: 组长 | J12: =VLOOKUP(B12,[3]加班情况分析!D:G,4,FALSE) -> 2.7478302 | K12: =VLOOKUP(B12,[3]加班情况分析!D:H,5,FALSE) -> TRUE | L12: =VLOOKUP(B12,[3]加班情况分析!D:L,6,FALSE) -> 3 | M12: =VLOOKUP($B12,[3]加班情况分析!$D:$L,7,FALSE) -> 5 | N12: =VLOOKUP($B12,[3]加班情况分析!$D:$L,8,FALSE) -> 42 | O12: =VLOOKUP(B12,[3]加班情况分析!D:L,9,FALSE) -> 3 | R12: =VLOOKUP(B12,[3]主管应用系统数量!I:J,2,FALSE) -> 1 | S12: 5 | T12: =VLOOKUP(B12,[3]二季度变更任务!A:B,2,FALSE) -> 2 | U12: =VLOOKUP(B12,[3]三季度变更任务!A:B,2,FALSE) -> 2 | V12: =VLOOKUP(B12,[3]责任事件及缺陷!A:B,2,FALSE) -> 1 | W12: 超负荷 | X12: 大数据集群运维监控治理、数仓任务调优、hadoop集群信创、分析圈客一体化、分行数字化、一表通、标签管理平台 | Y12: 大数据平台支持组负责工作，hadoop平台治理运维，hadoop信创调研 | Z12: 0.7 | AA12: 一体化运营平台cdp技术负责人 | AB12: 0.3 | AD12: 李天卓 | AE12: 基本适配 | AF12: 超负荷
A13: 11 | B13: 李天卓 | C13: 数据平台部 | D13: 运维支持组 | E13: 男 | F13: 5 | G13: 研究生 | H13: 上海师范大学 | I13: 骨干 | J13: =VLOOKUP(B13,[3]加班情况分析!D:G,4,FALSE) -> 2.278179 | K13: =VLOOKUP(B13,[3]加班情况分析!D:H,5,FALSE) -> TRUE | L13: =VLOOKUP(B13,[3]加班情况分析!D:L,6,FALSE) -> 3 | M13: =VLOOKUP($B13,[3]加班情况分析!$D:$L,7,FALSE) -> 33 | N13: =VLOOKUP($B13,[3]加班情况分析!$D:$L,8,FALSE) -> 11 | O13: =VLOOKUP(B13,[3]加班情况分析!D:L,9,FALSE) -> 7 | R13: =VLOOKUP(B13,[3]主管应用系统数量!I:J,2,FALSE) -> 2 | S13: 1 | U13: =VLOOKUP(B13,[3]三季度变更任务!A:B,2,FALSE) -> 1 | W13: 超负荷 | X13: 大数据平台运维优化、计算区平台开发治理、大数据规范优化修订、平台其他疑难杂症解决 | Y13: hadoop平台治理运维，hadoop信创调研。 | Z13: 0.6 | AA13: 司库数据中台建设牵头架构师，技术负责人 | AB13: 0.4 | AD13: 史朋飞 | AE13: 基本适配 | AF13: 超负荷
A14: 70 | B14: 吴小倩 | C14: 数据开发部 | D14: 应用开发组/监管报送 | E14: 女 | F14: 3 | G14: 大学本科 | H14: 电子科技大学 | I14: / | J14: =VLOOKUP(B14,[3]加班情况分析!D:G,4,FALSE) -> 3.0573878 | K14: =VLOOKUP(B14,[3]加班情况分析!D:H,5,FALSE) -> TRUE | L14: =VLOOKUP(B14,[3]加班情况分析!D:L,6,FALSE) -> 6 | M14: =VLOOKUP($B14,[3]加班情况分析!$D:$L,7,FALSE) -> 11 | N14: =VLOOKUP($B14,[3]加班情况分析!$D:$L,8,FALSE) -> 17 | O14: =VLOOKUP(B14,[3]加班情况分析!D:L,9,FALSE) -> 18 | P14: =VLOOKUP(B14,'[3]牵头项目（当前进行中）'!A:B,2,FALSE) -> 2 | Q14: =VLOOKUP(B14,'[3]牵头需求（当前进行中）'!A:B,2,FALSE) -> 5 | R14: =VLOOKUP(B14,[3]主管应用系统数量!I:J,2,FALSE) -> 1 | S14: 2 | U14: =VLOOKUP(B14,[3]三季度变更任务!A:B,2,FALSE) -> 14 | V14: =VLOOKUP(B14,[3]责任事件及缺陷!A:B,2,FALSE) -> 1 | W14: 超负荷 | X14: 审计署报送2.0、客户风险、支付信息报送、信息科技非现场监管 | Y14: 审计署报送2.0、客户风险、支付信息报送、信息科技非现场监管 | Z14: 1 | AE14: 基本适配 | AF14: 适中
A15: 13 | B15: 伍恒 | C15: 数据平台部 | D15: 工具开发组 | E15: 男 | F15: 7 | G15: 研究生 | H15: 武汉科技大学 | I15: 骨干 | J15: =VLOOKUP(B15,[3]加班情况分析!D:G,4,FALSE) -> 2.7303723 | K15: =VLOOKUP(B15,[3]加班情况分析!D:H,5,FALSE) -> TRUE | L15: =VLOOKUP(B15,[3]加班情况分析!D:L,6,FALSE) -> 5 | M15: =VLOOKUP($B15,[3]加班情况分析!$D:$L,7,FALSE) -> 25 | N15: =VLOOKUP($B15,[3]加班情况分析!$D:$L,8,FALSE) -> 8 | O15: =VLOOKUP(B15,[3]加班情况分析!D:L,9,FALSE) -> 9 | P15: =VLOOKUP(B15,'[3]牵头项目（当前进行中）'!A:B,2,FALSE) -> 1 | Q15: =VLOOKUP(B15,'[3]牵头需求（当前进行中）'!A:B,2,FALSE) -> 1 | R15: =VLOOKUP(B15,[3]主管应用系统数量!I:J,2,FALSE) -> 2 | S15: 2 | T15: =VLOOKUP(B15,[3]二季度变更任务!A:B,2,FALSE) -> 11 | U15: =VLOOKUP(B15,[3]三季度变更任务!A:B,2,FALSE) -> 38 | W15: 超负荷 | X15: 数据采集 | Y15: 数据采集后端开发 | Z15: 1 | AD15: 濮敏 | AE15: 基本适配 | AF15: 适中
A16: 14 | B16: 王正超 | C16: 数据平台部 | D16: 应用开发组 | E16: 男 | F16: 5 | G16: 研究生 | H16: 北京交通大学 | I16: 骨干 | J16: =VLOOKUP(B16,[3]加班情况分析!D:G,4,FALSE) -> 2.746523 | K16: =VLOOKUP(B16,[3]加班情况分析!D:H,5,FALSE) -> TRUE | L16: =VLOOKUP(B16,[3]加班情况分析!D:L,6,FALSE) -> 6 | M16: =VLOOKUP($B16,[3]加班情况分析!$D:$L,7,FALSE) -> 9 | N16: =VLOOKUP($B16,[3]加班情况分析!$D:$L,8,FALSE) -> 33 | O16: =VLOOKUP(B16,[3]加班情况分析!D:L,9,FALSE) -> 10 | P16: =VLOOKUP(B16,'[3]牵头项目（当前进行中）'!A:B,2,FALSE) -> 1 | Q16: =VLOOKUP(B16,'[3]牵头需求（当前进行中）'!A:B,2,FALSE) -> 14 | R16: =VLOOKUP(B16,[3]主管应用系统数量!I:J,2,FALSE) -> 1 | S16: 3 | T16: =VLOOKUP(B16,[3]二季度变更任务!A:B,2,FALSE) -> 14 | U16: =VLOOKUP(B16,[3]三季度变更任务!A:B,2,FALSE) -> 16 | V16: =VLOOKUP(B16,[3]责任事件及缺陷!A:B,2,FALSE) -> 2 | W16: 超负荷 | X16: CRM、PCCM、数库外部数据 | Y16: CRM小组负责人，主要负责对公crm，领导零售和同业crm | Z16: 1 | AD16: 佟嘉欣 | AE16: 基本适配 | AF16: 超负荷
A17: 15 | B17: 嵇雅娟 | C17: 数据平台部 | D17: 应用开发组 | E17: 女 | F17: 10 | G17: 大学本科 | H17: 中国科学技术大学 | I17: 骨干 | J17: =VLOOKUP(B17,[3]加班情况分析!D:G,4,FALSE) -> 1.1071405 | K17: =VLOOKUP(B17,[3]加班情况分析!D:H,5,FALSE) -> FALSE | L17: =VLOOKUP(B17,[3]加班情况分析!D:L,6,FALSE) -> 21 | M17: =VLOOKUP($B17,[3]加班情况分析!$D:$L,7,FALSE) -> 26 | N17: =VLOOKUP($B17,[3]加班情况分析!$D:$L,8,FALSE) -> 4 | O17: =VLOOKUP(B17,[3]加班情况分析!D:L,9,FALSE) -> 0 | Q17: =VLOOKUP(B17,'[3]牵头需求（当前进行中）'!A:B,2,FALSE) -> 5 | R17: =VLOOKUP(B17,[3]主管应用系统数量!I:J,2,FALSE) -> 3 | S17: 2 | T17: =VLOOKUP(B17,[3]二季度变更任务!A:B,2,FALSE) -> 5 | U17: =VLOOKUP(B17,[3]三季度变更任务!A:B,2,FALSE) -> 9 | V17: =VLOOKUP(B17,[3]责任事件及缺陷!A:B,2,FALSE) -> 3 | W17: 适中 | X17: 反洗钱报送、反洗钱综合管理系统、自贸区报送、智芯、技改、信创 | Y17: 反洗钱小组负责人 | Z17: 1 | AD17: 张顺 | AE17: 基本适配 | AF17: 适中
A18: 16 | B18: 鞠爱宁 | C18: 数据平台部 | D18: 数据服务组 | E18: 男 | F18: 7 | G18: 研究生 | H18: 上海大学 | I18: 组长 | J18: =VLOOKUP(B18,[3]加班情况分析!D:G,4,FALSE) -> 3.1462903 | K18: =VLOOKUP(B18,[3]加班情况分析!D:H,5,FALSE) -> TRUE | L18: =VLOOKUP(B18,[3]加班情况分析!D:L,6,FALSE) -> 1 | M18: =VLOOKUP($B18,[3]加班情况分析!$D:$L,7,FALSE) -> 6 | N18: =VLOOKUP($B18,[3]加班情况分析!$D:$L,8,FALSE) -> 38 | O18: =VLOOKUP(B18,[3]加班情况分析!D:L,9,FALSE) -> 17 | Q18: =VLOOKUP(B18,'[3]牵头需求（当前进行中）'!A:B,2,FALSE) -> 1 | R18: =VLOOKUP(B18,[3]主管应用系统数量!I:J,2,FALSE) -> 1 | S18: 2 | T18: =VLOOKUP(B18,[3]二季度变更任务!A:B,2,FALSE) -> 10 | U18: =VLOOKUP(B18,[3]三季度变更任务!A:B,2,FALSE) -> 11 | V18: =VLOOKUP(B18,[3]责任事件及缺陷!A:B,2,FALSE) -> 2 | W18: 超负荷 | X18: 数据服务、实时平台、外数迁移、慧信工程 | Y18: 实时平台、数据服务中心、RAD | Z18: 0.6 | AA18: 外部数据、架构、面试 | AB18: 0.4 | AD18: 安新宜、刘金良 | AE18: 基本适配 | AF18: 适中
A19: 17 | B19: 魏佳翔 | C19: 数据平台部 | D19: 数据服务组 | E19: 男 | F19: 11 | G19: 大学本科 | H19: 大连海事大学 | I19: 组长 | J19: =VLOOKUP(B19,[3]加班情况分析!D:G,4,FALSE) -> 1.5513262 | K19: =VLOOKUP(B19,[3]加班情况分析!D:H,5,FALSE) -> FALSE | L19: =VLOOKUP(B19,[3]加班情况分析!D:L,6,FALSE) -> 34 | M19: =VLOOKUP($B19,[3]加班情况分析!$D:$L,7,FALSE) -> 14 | N19: =VLOOKUP($B19,[3]加班情况分析!$D:$L,8,FALSE) -> 8 | O19: =VLOOKUP(B19,[3]加班情况分析!D:L,9,FALSE) -> 6 | Q19: =VLOOKUP(B19,'[3]牵头需求（当前进行中）'!A:B,2,FALSE) -> 1 | S19: 2 | W19: 超负荷 | X19: 架构设计，UDAS、掌上行、RAD、RSD的应用开发和管理 | Y19: 应用开发组负责人，udas，掌上行 | Z19: 0.5 | AA19: 智能问数，司库风险模块 | AB19: 0.5 | AE19: 基本适配 | AF19: 超负荷
A20: 18 | B20: 杨婧 | C20: 智能创新部 | D20: AI产品运营组 | E20: 女 | F20: 4 | G20: 研究生 | H20: 中国科学技术大学 | I20: 组长 | J20: =VLOOKUP(B20,[3]加班情况分析!D:G,4,FALSE) -> 2.9616803 | K20: =VLOOKUP(B20,[3]加班情况分析!D:H,5,FALSE) -> TRUE | L20: =VLOOKUP(B20,[3]加班情况分析!D:L,6,FALSE) -> 7 | M20: =VLOOKUP($B20,[3]加班情况分析!$D:$L,7,FALSE) -> 11 | N20: =VLOOKUP($B20,[3]加班情况分析!$D:$L,8,FALSE) -> 26 | O20: =VLOOKUP(B20,[3]加班情况分析!D:L,9,FALSE) -> 17 | Q20: =VLOOKUP(B20,'[3]牵头需求（当前进行中）'!A:B,2,FALSE) -> 1 | R20: =VLOOKUP(B20,[3]主管应用系统数量!I:J,2,FALSE) -> 1 | S20: 2 | W20: 超负荷 | X20: 1、尽调助手 2、研报解读 3、数字化档案建设 4、风险合规智能化应用 5、办公助手建设 6、尽调报告辅助生成（hiagent智能体平台） 7、长文本智能分析优化需求 8、校招面试 | Y20: 尽调助手、数字化档案建设 | Z20: 0.5 | AA20: 研报解读 办公助手建设 | AB20: 0.2 | AC20: 协助团队负责人团队管理工作，负责AI产品运营组日常管理工作 材料准备工作：总行监管、分行监管、人行、以及其他公司的调研材料 | AD20: 无 | AE20: 基本适配 | AF20: 超负荷
A21: 19 | B21: 邱玥 | C21: 智能创新部 | D21: AI产品运营组 | E21: 女 | F21: 2 | G21: 研究生 | H21: 东华大学 | I21: 骨干 | J21: =VLOOKUP(B21,[3]加班情况分析!D:G,4,FALSE) -> 1.6532104 | K21: =VLOOKUP(B21,[3]加班情况分析!D:H,5,FALSE) -> FALSE | L21: =VLOOKUP(B21,[3]加班情况分析!D:L,6,FALSE) -> 7 | M21: =VLOOKUP($B21,[3]加班情况分析!$D:$L,7,FALSE) -> 47 | N21: =VLOOKUP($B21,[3]加班情况分析!$D:$L,8,FALSE) -> 5 | O21: =VLOOKUP(B21,[3]加班情况分析!D:L,9,FALSE) -> 2 | P21: =VLOOKUP(B21,'[3]牵头项目（当前进行中）'!A:B,2,FALSE) -> 1 | Q21: =VLOOKUP(B21,'[3]牵头需求（当前进行中）'!A:B,2,FALSE) -> 1 | R21: =VLOOKUP(B21,[3]主管应用系统数量!I:J,2,FALSE) -> 1 | S21: 2 | T21: =VLOOKUP(B21,[3]二季度变更任务!A:B,2,FALSE) -> 2 | U21: =VLOOKUP(B21,[3]三季度变更任务!A:B,2,FALSE) -> 4 | V21: =VLOOKUP(B21,[3]责任事件及缺陷!A:B,2,FALSE) -> 3 | W21: 适中 | X21: 1、零售CRM场景建设 2、数据部助理 3、知识运营体系建设 4、e搜技改&零星需求 | Y21: 零售CRM场景建设 | Z21: 0.4 | AA21: e搜技改&零星需求 | AB21: 0.3 | AD21: 蒋捷 | AE21: 基本适配 | AF21: 适中
A22: 20 | B22: 李响 | C22: 智能创新部 | D22: AI基础研发组 | E22: 男 | F22: 12 | G22: 大学本科 | H22: 哈尔滨工业大学 | I22: 组长 | J22: =VLOOKUP(B22,[3]加班情况分析!D:G,4,FALSE) -> 1.4479646 | K22: =VLOOKUP(B22,[3]加班情况分析!D:H,5,FALSE) -> FALSE | L22: =VLOOKUP(B22,[3]加班情况分析!D:L,6,FALSE) -> 25 | M22: =VLOOKUP($B22,[3]加班情况分析!$D:$L,7,FALSE) -> 21 | N22: =VLOOKUP($B22,[3]加班情况分析!$D:$L,8,FALSE) -> 6 | O22: =VLOOKUP(B22,[3]加班情况分析!D:L,9,FALSE) -> 3 | P22: =VLOOKUP(B22,'[3]牵头项目（当前进行中）'!A:B,2,FALSE) -> 2 | R22: =VLOOKUP(B22,[3]主管应用系统数量!I:J,2,FALSE) -> 2 | S22: 5 | T22: =VLOOKUP(B22,[3]二季度变更任务!A:B,2,FALSE) -> 16 | U22: =VLOOKUP(B22,[3]三季度变更任务!A:B,2,FALSE) -> 13 | V22: =VLOOKUP(B22,[3]责任事件及缺陷!A:B,2,FALSE) -> 1 | W22: 超负荷 | X22: 1、向量知识库项目 2、会话式人工智能服务技改 3、AIGC项目中客服场景建设 4、校招面试 | Y22: AIGC项目中客服场景建设 | Z22: 0.1 | AA22: 向量知识库建设 | AB22: 0.15 | AC22: "协助团队负责人团队管理工作，负责AI基础研发日常管理工作 | AD22: 无 | AE22: 任务难度略高/略低于个人能力 | AF22: 适中
A23: 21 | B23: 于中宝 | C23: 智能创新部 | D23: AI基础研发组 | E23: 男 | F23: 5 | G23: 研究生 | H23: 华东理工大学 | I23: 骨干 | J23: =VLOOKUP(B23,[3]加班情况分析!D:G,4,FALSE) -> 2.2854211 | K23: =VLOOKUP(B23,[3]加班情况分析!D:H,5,FALSE) -> TRUE | L23: =VLOOKUP(B23,[3]加班情况分析!D:L,6,FALSE) -> 3 | M23: =VLOOKUP($B23,[3]加班情况分析!$D:$L,7,FALSE) -> 36 | N23: =VLOOKUP($B23,[3]加班情况分析!$D:$L,8,FALSE) -> 14 | O23: =VLOOKUP(B23,[3]加班情况分析!D:L,9,FALSE) -> 9 | P23: =VLOOKUP(B23,'[3]牵头项目（当前进行中）'!A:B,2,FALSE) -> 2 | Q23: =VLOOKUP(B23,'[3]牵头需求（当前进行中）'!A:B,2,FALSE) -> 2 | R23: =VLOOKUP(B23,[3]主管应用系统数量!I:J,2,FALSE) -> 1 | S23: 3 | T23: =VLOOKUP(B23,[3]二季度变更任务!A:B,2,FALSE) -> 9 | U23: =VLOOKUP(B23,[3]三季度变更任务!A:B,2,FALSE) -> 5 | W23: 超负荷 | X23: 1、关联图谱平台技改项目 2、大模型应用项目（800w项目需求对接梳理工作） 3、知识图谱在员工异常行为检测方面的应用 4、隐私计算外部产品引入 5、AI手机银行2.0 6、校招面试 | Y23: 大模型应用项目、关联图谱平台技改项目 | Z23: 0.4 | AA23: 隐私计算外部产品引入、知识图谱在员工异常行为检测方面的应用 | AB23: 0.35 | AE23: 基本适配 | AF23: 超负荷
A24: 22 | B24: 李梦霄 | C24: 智能创新部 | D24: 风险模型团队 | E24: 女 | F24: 5 | G24: 研究生 | H24: 华东理工大学 | I24: 组长 | J24: =VLOOKUP(B24,[3]加班情况分析!D:G,4,FALSE) -> 1.9988183 | K24: =VLOOKUP(B24,[3]加班情况分析!D:H,5,FALSE) -> FALSE | L24: =VLOOKUP(B24,[3]加班情况分析!D:L,6,FALSE) -> 11 | M24: =VLOOKUP($B24,[3]加班情况分析!$D:$L,7,FALSE) -> 19 | N24: =VLOOKUP($B24,[3]加班情况分析!$D:$L,8,FALSE) -> 27 | O24: =VLOOKUP(B24,[3]加班情况分析!D:L,9,FALSE) -> 2 | P24: =VLOOKUP(B24,'[3]牵头项目（当前进行中）'!A:B,2,FALSE) -> 1 | S24: 2 | W24: 适中 | X24: 1、模型管理 2、反电诈统筹 3、AI产品问题协助统筹 4、信用风险模型 5、校招面试 | Y24: 反电诈工作牵头 | Z24: 0.3 | AA24: AI模型资产 | AB24: 0.4 | AC24: 协助团队负责人团队管理工作，负责风险模型组日常管理工作 材料准备工作：协助编写汇报材料准备工作 | AD24: 无 | AE24: 基本适配 | AF24: 适中
A25: 23 | B25: 于俊杰 | C25: 智能创新部 | D25: 风险模型团队 | E25: 男 | F25: 2 | G25: 研究生 | H25: 华东理工大学 | I25: 骨干候选人 | J25: =VLOOKUP(B25,[3]加班情况分析!D:G,4,FALSE) -> 1.867327 | K25: =VLOOKUP(B25,[3]加班情况分析!D:H,5,FALSE) -> FALSE | L25: =VLOOKUP(B25,[3]加班情况分析!D:L,6,FALSE) -> 20 | M25: =VLOOKUP($B25,[3]加班情况分析!$D:$L,7,FALSE) -> 24 | N25: =VLOOKUP($B25,[3]加班情况分析!$D:$L,8,FALSE) -> 9 | O25: =VLOOKUP(B25,[3]加班情况分析!D:L,9,FALSE) -> 8 | P25: =VLOOKUP(B25,'[3]牵头项目（当前进行中）'!A:B,2,FALSE) -> 1 | R25: =VLOOKUP(B25,[3]主管应用系统数量!I:J,2,FALSE) -> 1 | S25: 1 | U25: =VLOOKUP(B25,[3]三季度变更任务!A:B,2,FALSE) -> 9 | W25: 适中 | X25: 1、MLOPS开发建设 2、大数据建模平台运维 | Y25: MLOPS开发建设 | Z25: 0.6 | AA25: 大数据建模平台运维 | AB25: 0.4 | AD25: 无 | AE25: 基本适配 | AF25: 适中
A26: 24 | B26: 周影 | C26: 数据开发部 | D26: 仓库开发组 | E26: 女 | F26: 6 | G26: 研究生 | H26: 湖南大学 | I26: 骨干 | J26: =VLOOKUP(B26,[3]加班情况分析!D:G,4,FALSE) -> 3.3079483 | K26: =VLOOKUP(B26,[3]加班情况分析!D:H,5,FALSE) -> TRUE | L26: =VLOOKUP(B26,[3]加班情况分析!D:L,6,FALSE) -> 0 | M26: =VLOOKUP($B26,[3]加班情况分析!$D:$L,7,FALSE) -> 12 | N26: =VLOOKUP($B26,[3]加班情况分析!$D:$L,8,FALSE) -> 30 | O26: =VLOOKUP(B26,[3]加班情况分析!D:L,9,FALSE) -> 15 | Q26: =VLOOKUP(B26,'[3]牵头需求（当前进行中）'!A:B,2,FALSE) -> 3 | S26: 1 | W26: 超负荷 | X26: 智芯工程、整合模型（核心存款）、零售领域模型设计 | Y26: 整合模型（核心存款）、零售领域模型设计 | Z26: 1 | AE26: 基本适配 | AF26: 适中
A27: 25 | B27: 姚志环 | C27: 数据开发部 | D27: 仓库开发组 | E27: 女 | F27: 5 | G27: 研究生 | H27: 华东理工大学 | I27: 骨干 | J27: =VLOOKUP(B27,[3]加班情况分析!D:G,4,FALSE) -> 1.9892433 | K27: =VLOOKUP(B27,[3]加班情况分析!D:H,5,FALSE) -> FALSE | L27: =VLOOKUP(B27,[3]加班情况分析!D:L,6,FALSE) -> 6 | M27: =VLOOKUP($B27,[3]加班情况分析!$D:$L,7,FALSE) -> 33 | N27: =VLOOKUP($B27,[3]加班情况分析!$D:$L,8,FALSE) -> 14 | O27: =VLOOKUP(B27,[3]加班情况分析!D:L,9,FALSE) -> 5 | S27: 1 | T27: =VLOOKUP(B27,[3]二季度变更任务!A:B,2,FALSE) -> 4 | U27: =VLOOKUP(B27,[3]三季度变更任务!A:B,2,FALSE) -> 7 | W27: 适中 | X27: 两大工程、对公领域模型设计、票易贷项目 | Y27: 对公领域模型设计 | Z27: 1 | AE27: 基本适配 | AF27: 适中
A28: 26 | B28: 林幸 | C28: 数据开发部 | D28: 仓库开发组 | E28: 女 | F28: 3 | G28: 研究生 | H28: 东北大学 | I28: 骨干 | J28: =VLOOKUP(B28,[3]加班情况分析!D:G,4,FALSE) -> 3.2112524 | K28: =VLOOKUP(B28,[3]加班情况分析!D:H,5,FALSE) -> TRUE | L28: =VLOOKUP(B28,[3]加班情况分析!D:L,6,FALSE) -> 5 | M28: =VLOOKUP($B28,[3]加班情况分析!$D:$L,7,FALSE) -> 7 | N28: =VLOOKUP($B28,[3]加班情况分析!$D:$L,8,FALSE) -> 30 | O28: =VLOOKUP(B28,[3]加班情况分析!D:L,9,FALSE) -> 15 | P28: =VLOOKUP(B28,'[3]牵头项目（当前进行中）'!A:B,2,FALSE) -> 1 | Q28: =VLOOKUP(B28,'[3]牵头需求（当前进行中）'!A:B,2,FALSE) -> 3 | R28: =VLOOKUP(B28,[3]主管应用系统数量!I:J,2,FALSE) -> 1 | S28: 1 | T28: =VLOOKUP(B28,[3]二季度变更任务!A:B,2,FALSE) -> 8 | U28: =VLOOKUP(B28,[3]三季度变更任务!A:B,2,FALSE) -> 9 | W28: 超负荷 | X28: 两大工程整合模型、计财集市、FTP项目 | Y28: 计财集市、司库项目 | Z28: 1 | AE28: 基本适配 | AF28: 适中
A29: 27 | B29: 骆静龙 | C29: 数据开发部 | D29: 应用开发组 | E29: 男 | F29: 2 | G29: 大学本科 | H29: 华东师范大学 | I29: 骨干 | J29: =VLOOKUP(B29,[3]加班情况分析!D:G,4,FALSE) -> 2.6957957 | K29: =VLOOKUP(B29,[3]加班情况分析!D:H,5,FALSE) -> TRUE | L29: =VLOOKUP(B29,[3]加班情况分析!D:L,6,FALSE) -> 5 | M29: =VLOOKUP($B29,[3]加班情况分析!$D:$L,7,FALSE) -> 10 | N29: =VLOOKUP($B29,[3]加班情况分析!$D:$L,8,FALSE) -> 33 | O29: =VLOOKUP(B29,[3]加班情况分析!D:L,9,FALSE) -> 11 | Q29: =VLOOKUP(B29,'[3]牵头需求（当前进行中）'!A:B,2,FALSE) -> 1 | S29: 1 | T29: =VLOOKUP(B29,[3]二季度变更任务!A:B,2,FALSE) -> 15 | U29: =VLOOKUP(B29,[3]三季度变更任务!A:B,2,FALSE) -> 10 | V29: =VLOOKUP(B29,[3]责任事件及缺陷!A:B,2,FALSE) -> 2 | W29: 超负荷 | X29: NRP集市（UDAS,hadoop侧） | Y29: NRP集市（UDAS,hadoop侧） | Z29: 1 | AE29: 基本适配 | AF29: 适中
A30: 28 | B30: 王言哲 | C30: 数据开发部 | D30: 应用开发组 | E30: 男 | F30: 3 | G30: 大学本科 | H30: 华东师范大学 | I30: 骨干 | J30: =VLOOKUP(B30,[3]加班情况分析!D:G,4,FALSE) -> 2.2557423 | K30: =VLOOKUP(B30,[3]加班情况分析!D:H,5,FALSE) -> FALSE | L30: =VLOOKUP(B30,[3]加班情况分析!D:L,6,FALSE) -> 1 | M30: =VLOOKUP($B30,[3]加班情况分析!$D:$L,7,FALSE) -> 39 | N30: =VLOOKUP($B30,[3]加班情况分析!$D:$L,8,FALSE) -> 17 | O30: =VLOOKUP(B30,[3]加班情况分析!D:L,9,FALSE) -> 4 | Q30: =VLOOKUP(B30,'[3]牵头需求（当前进行中）'!A:B,2,FALSE) -> 8 | S30: 1 | T30: =VLOOKUP(B30,[3]二季度变更任务!A:B,2,FALSE) -> 20 | U30: =VLOOKUP(B30,[3]三季度变更任务!A:B,2,FALSE) -> 19 | W30: 超负荷 | X30: 反洗钱报送 | Y30: 反洗钱报送 | Z30: 1 | AE30: 基本适配 | AF30: 适中
A31: 29 | B31: 马富强 | C31: 数据开发部 | D31: 仓库开发组 | E31: 男 | F31: 7 | G31: 大学本科 | H31: 上海理工大学 | I31: 骨干 | J31: =VLOOKUP(B31,[3]加班情况分析!D:G,4,FALSE) -> 3.151064 | K31: =VLOOKUP(B31,[3]加班情况分析!D:H,5,FALSE) -> TRUE | L31: =VLOOKUP(B31,[3]加班情况分析!D:L,6,FALSE) -> 1 | M31: =VLOOKUP($B31,[3]加班情况分析!$D:$L,7,FALSE) -> 2 | N31: =VLOOKUP($B31,[3]加班情况分析!$D:$L,8,FALSE) -> 50 | O31: =VLOOKUP(B31,[3]加班情况分析!D:L,9,FALSE) -> 6 | Q31: =VLOOKUP(B31,'[3]牵头需求（当前进行中）'!A:B,2,FALSE) -> 1 | S31: 1 | T31: =VLOOKUP(B31,[3]二季度变更任务!A:B,2,FALSE) -> 10 | U31: =VLOOKUP(B31,[3]三季度变更任务!A:B,2,FALSE) -> 13 | V31: =VLOOKUP(B31,[3]责任事件及缺陷!A:B,2,FALSE) -> 1 | W31: 超负荷 | X31: 风险集市牵头人 | Y31: 风险集市牵头人 | Z31: 1 | AE31: 基本适配 | AF31: 适中
A32: 30 | B32: 胡帆 | C32: 数据平台部 | D32: 数据服务组 | E32: 男 | F32: 3 | G32: 研究生 | H32: 华东理工大学 | I32: 骨干 | J32: =VLOOKUP(B32,[3]加班情况分析!D:G,4,FALSE) -> 2.6456657 | K32: =VLOOKUP(B32,[3]加班情况分析!D:H,5,FALSE) -> TRUE | L32: =VLOOKUP(B32,[3]加班情况分析!D:L,6,FALSE) -> 12 | M32: =VLOOKUP($B32,[3]加班情况分析!$D:$L,7,FALSE) -> 4 | N32: =VLOOKUP($B32,[3]加班情况分析!$D:$L,8,FALSE) -> 29 | O32: =VLOOKUP(B32,[3]加班情况分析!D:L,9,FALSE) -> 13 | R32: =VLOOKUP(B32,[3]主管应用系统数量!I:J,2,FALSE) -> 1 | S32: 1 | T32: =VLOOKUP(B32,[3]二季度变更任务!A:B,2,FALSE) -> 8 | U32: =VLOOKUP(B32,[3]三季度变更任务!A:B,2,FALSE) -> 10 | W32: 适中 | X32: RSD应用负责人 | Y32: RSD | Z32: 0.8 | AA32: 架构、AI代码助手 | AB32: 0.2 | AD32: 魏佳翔、曾敏锐 | AE32: 基本适配 | AF32: 适中
A33: 31 | B33: 陆凯华 | C33: 数据平台部 | D33: 数据服务组 | E33: 男 | F33: `1 | G33: 研究生 | H33: 苏州大学 | I33: 骨干 | J33: =VLOOKUP(B33,[3]加班情况分析!D:G,4,FALSE) -> 3.9148197 | K33: =VLOOKUP(B33,[3]加班情况分析!D:H,5,FALSE) -> TRUE | L33: =VLOOKUP(B33,[3]加班情况分析!D:L,6,FALSE) -> 11 | M33: =VLOOKUP($B33,[3]加班情况分析!$D:$L,7,FALSE) -> 11 | N33: =VLOOKUP($B33,[3]加班情况分析!$D:$L,8,FALSE) -> 8 | O33: =VLOOKUP(B33,[3]加班情况分析!D:L,9,FALSE) -> 27 | P33: =VLOOKUP(B33,'[3]牵头项目（当前进行中）'!A:B,2,FALSE) -> 1 | Q33: =VLOOKUP(B33,'[3]牵头需求（当前进行中）'!A:B,2,FALSE) -> 4 | R33: =VLOOKUP(B33,[3]主管应用系统数量!I:J,2,FALSE) -> 3 | S33: 4 | T33: =VLOOKUP(B33,[3]二季度变更任务!A:B,2,FALSE) -> 21 | U33: =VLOOKUP(B33,[3]三季度变更任务!A:B,2,FALSE) -> 35 | V33: =VLOOKUP(B33,[3]责任事件及缺陷!A:B,2,FALSE) -> 3 | W33: 超负荷 | X33: 联机服务集群、外部数据、企业资金流共享平台 | Y33: 外部数据、联机服务集群、RAD | Z33: 0.8 | AA33: 企业资金流共享平台 | AB33: 0.2 | AC33: 流程分析平台 | AD33: 任欣宇 | AE33: 基本适配 | AF33: 适中
A34: 32 | B34: 朱文川 | C34: 数据平台部 | D34: 工具开发组 | E34: 男 | F34: 2 | G34: 研究生 | H34: 上海大学 | I34: 骨干 | J34: =VLOOKUP(B34,[3]加班情况分析!D:G,4,FALSE) -> 1.5535153 | K34: =VLOOKUP(B34,[3]加班情况分析!D:H,5,FALSE) -> FALSE | L34: =VLOOKUP(B34,[3]加班情况分析!D:L,6,FALSE) -> 16 | M34: =VLOOKUP($B34,[3]加班情况分析!$D:$L,7,FALSE) -> 36 | N34: =VLOOKUP($B34,[3]加班情况分析!$D:$L,8,FALSE) -> 0 | O34: =VLOOKUP(B34,[3]加班情况分析!D:L,9,FALSE) -> 6 | S34: 2 | T34: =VLOOKUP(B34,[3]二季度变更任务!A:B,2,FALSE) -> 6 | U34: =VLOOKUP(B34,[3]三季度变更任务!A:B,2,FALSE) -> 6 | W34: 适中 | X34: Stella、调度、dataops开发 | Y34: dataops数据测试模块开发 | Z34: 0.8 | AA34: 调度开发 | AB34: 0.2 | AD34: 陈玉思 | AE34: 基本适配 | AF34: 适中
A35: 33 | B35: 崔建文 | C35: 智能创新部 | D35: 模型开发组 | E35: 男 | F35: 4 | G35: 研究生 | H35: 厦门大学 | I35: 骨干 | J35: =VLOOKUP(B35,[3]加班情况分析!D:G,4,FALSE) -> 2.7256206 | K35: =VLOOKUP(B35,[3]加班情况分析!D:H,5,FALSE) -> TRUE | L35: =VLOOKUP(B35,[3]加班情况分析!D:L,6,FALSE) -> 9 | M35: =VLOOKUP($B35,[3]加班情况分析!$D:$L,7,FALSE) -> 4 | N35: =VLOOKUP($B35,[3]加班情况分析!$D:$L,8,FALSE) -> 25 | O35: =VLOOKUP(B35,[3]加班情况分析!D:L,9,FALSE) -> 9 | P35: =VLOOKUP(B35,'[3]牵头项目（当前进行中）'!A:B,2,FALSE) -> 1 | Q35: =VLOOKUP(B35,'[3]牵头需求（当前进行中）'!A:B,2,FALSE) -> 2 | S35: 1 | W35: 适中 | X35: 1、反电诈模型建设 2、智能财报分析 3、校招面试 | Y35: 反电诈联合办公（牵头） | Z35: 0.6 | AA35: 智能财报分析 | AB35: 0.3 | AD35: 无 | AE35: 基本适配 | AF35: 适中
A36: 34 | B36: 贾世林 | C36: 智能创新部 | D36: AI基础研发组 | E36: 男 | F36: 4 | G36: 研究生 | H36: 上海师范大学 | I36: 骨干 | J36: =VLOOKUP(B36,[3]加班情况分析!D:G,4,FALSE) -> 1.9630242 | K36: =VLOOKUP(B36,[3]加班情况分析!D:H,5,FALSE) -> FALSE | L36: =VLOOKUP(B36,[3]加班情况分析!D:L,6,FALSE) -> 12 | M36: =VLOOKUP($B36,[3]加班情况分析!$D:$L,7,FALSE) -> 33 | N36: =VLOOKUP($B36,[3]加班情况分析!$D:$L,8,FALSE) -> 12 | O36: =VLOOKUP(B36,[3]加班情况分析!D:L,9,FALSE) -> 5 | P36: =VLOOKUP(B36,'[3]牵头项目（当前进行中）'!A:B,2,FALSE) -> 1 | Q36: =VLOOKUP(B36,'[3]牵头需求（当前进行中）'!A:B,2,FALSE) -> 1 | R36: =VLOOKUP(B36,[3]主管应用系统数量!I:J,2,FALSE) -> 1 | S36: 1 | T36: =VLOOKUP(B36,[3]二季度变更任务!A:B,2,FALSE) -> 7 | U36: =VLOOKUP(B36,[3]三季度变更任务!A:B,2,FALSE) -> 12 | V36: =VLOOKUP(B36,[3]责任事件及缺陷!A:B,2,FALSE) -> 1 | W36: 超负荷 | X36: AIGC生成式技术综合应用之企业级知识问答体系建设 1.大模型底座（千帆）平台负责人 2.负责大模型基础资源(GPU)以及各类开源模型行内引入、部署以及维护 3.大模型网关建设 4.AIGC生成式技术综合应用之企业级知识问答体系建设项目经理 5、校招面试 | Y36: 大模型基础服务部署、大模型平台建设 | Z36: 0.6 | AA36: 大模型网关 | AB36: 0.2 | AD36: 无 | AE36: 任务难度略高/略低于个人能力 | AF36: 超负荷
A37: 35 | B37: 陆文捷 | C37: 智能创新部 | D37: 模型开发组 | E37: 女 | F37: 1 | G37: 研究生 | H37: 苏州大学 | I37: 骨干 | J37: =VLOOKUP(B37,[3]加班情况分析!D:G,4,FALSE) -> 1.6193109 | K37: =VLOOKUP(B37,[3]加班情况分析!D:H,5,FALSE) -> FALSE | L37: =VLOOKUP(B37,[3]加班情况分析!D:L,6,FALSE) -> 15 | M37: =VLOOKUP($B37,[3]加班情况分析!$D:$L,7,FALSE) -> 20 | N37: =VLOOKUP($B37,[3]加班情况分析!$D:$L,8,FALSE) -> 16 | O37: =VLOOKUP(B37,[3]加班情况分析!D:L,9,FALSE) -> 1 | S37: 0 | W37: 不饱和 | X37: 1、智能对标/安全管控模型 2、数据血缘链路梳理 3、脚本转白皮书 | Y37: 脚本转白皮书、基于大模型的数据血缘链路梳理 | Z37: 0.5 | AA37: 智能对标/安全管控模型建设 | AB37: 0.5 | AD37: 无 | AE37: 基本适配 | AF37: 适中
A38: 36 | B38: 白迪 | C38: 数据平台部 | D38: 工具开发组&数据服务组负责人 | E38: 男 | F38: 6 | G38: 研究生 | H38: 东华大学 | I38: / | J38: =VLOOKUP(B38,[3]加班情况分析!D:G,4,FALSE) -> 2.0511558 | K38: =VLOOKUP(B38,[3]加班情况分析!D:H,5,FALSE) -> TRUE | L38: =VLOOKUP(B38,[3]加班情况分析!D:L,6,FALSE) -> 9 | M38: =VLOOKUP($B38,[3]加班情况分析!$D:$L,7,FALSE) -> 35 | N38: =VLOOKUP($B38,[3]加班情况分析!$D:$L,8,FALSE) -> 3 | O38: =VLOOKUP(B38,[3]加班情况分析!D:L,9,FALSE) -> 9 | S38: 0 | X38: 工具开发组&数据服务组管理工作 | Y38: 参与应用设计，推进团队应用自主研发 | Z38: 1 | AD38: 吴证 | AE38: 基本适配 | AF38: 适中
A39: 37 | B39: 濮敏 | C39: 数据平台部 | D39: 工具开发组 | E39: 女 | F39: 4 | G39: 研究生 | H39: 华东师范大学 | I39: / | J39: =VLOOKUP(B39,[3]加班情况分析!D:G,4,FALSE) -> 0.62686441 | K39: =VLOOKUP(B39,[3]加班情况分析!D:H,5,FALSE) -> FALSE | L39: =VLOOKUP(B39,[3]加班情况分析!D:L,6,FALSE) -> 56 | M39: =VLOOKUP($B39,[3]加班情况分析!$D:$L,7,FALSE) -> 3 | N39: =VLOOKUP($B39,[3]加班情况分析!$D:$L,8,FALSE) -> 0 | O39: =VLOOKUP(B39,[3]加班情况分析!D:L,9,FALSE) -> 0 | R39: =VLOOKUP(B39,[3]主管应用系统数量!I:J,2,FALSE) -> 1 | S39: 2 | T39: =VLOOKUP(B39,[3]二季度变更任务!A:B,2,FALSE) -> 2 | W39: 不饱和 | X39: 数据采集 | Y39: 数据采集前端开发 | Z39: 1 | AD39: 伍恒 | AE39: 基本适配 | AF39: 适中
A40: 38 | B40: 沈志贇 | C40: 数据平台部 | D40: 工具开发组 | E40: 男 | F40: 2 | G40: 大学本科 | H40: 上海大学 | I40: / | J40: =VLOOKUP(B40,[3]加班情况分析!D:G,4,FALSE) -> 1.4096553 | K40: =VLOOKUP(B40,[3]加班情况分析!D:H,5,FALSE) -> FALSE | L40: =VLOOKUP(B40,[3]加班情况分析!D:L,6,FALSE) -> 16 | M40: =VLOOKUP($B40,[3]加班情况分析!$D:$L,7,FALSE) -> 36 | N40: =VLOOKUP($B40,[3]加班情况分析!$D:$L,8,FALSE) -> 0 | O40: =VLOOKUP(B40,[3]加班情况分析!D:L,9,FALSE) -> 2 | Q40: =VLOOKUP(B40,'[3]牵头需求（当前进行中）'!A:B,2,FALSE) -> 2 | R40: =VLOOKUP(B40,[3]主管应用系统数量!I:J,2,FALSE) -> 1 | S40: 1 | T40: =VLOOKUP(B40,[3]二季度变更任务!A:B,2,FALSE) -> 1 | U40: =VLOOKUP(B40,[3]三季度变更任务!A:B,2,FALSE) -> 3 | W40: 适中 | X40: 数据采集 | Y40: 数据采集后端开发 | Z40: 1 | AD40: 伍恒 | AE40: 基本适配 | AF40: 适中
...

Sheet 3 人员画像-年
A1: 年度观测：人才梯队健康度/结构合理性、高潜力员工挖掘、专业水平提升、流动性分析、员工360环评等。
A2: 类别 | B2: 序号 | C2: 指标名称 | D2: 指标口径 | E2: 数据来源 | F2: 更新频率 | G2: 基础数据是否已获取 | H2: 配套动作
A3: 基本信息 （人才梯队健康度） | B3: =ROW()-2 -> 1 | C3: 年龄 | E3: EHR系统 | F3: - | G3: 是
B4: =ROW()-2 -> 2 | C4: 性别 | E4: EHR系统 | F4: - | G4: 是
B5: =ROW()-2 -> 3 | C5: 学历 | E5: EHR系统 | F5: - | G5: 是
B6: =ROW()-2 -> 4 | C6: 专业 | E6: EHR系统 | F6: - | G6: 是
B7: =ROW()-2 -> 5 | C7: 司龄 | E7: EHR系统 | F7: 年度 | G7: 是
B8: =ROW()-2 -> 6 | C8: 工龄 | E8: EHR系统 | F8: 年度 | G8: 是
B9: =ROW()-2 -> 7 | C9: 所在科室 | E9: EHR系统 | F9: 年度 | G9: 是
B10: =ROW()-2 -> 8 | C10: 所在组 | E10: EHR系统 | F10: 年度 | G10: 是
B11: =ROW()-2 -> 9 | C11: 校招/社招标识 | E11: EHR系统 | F11: 年度 | G11: 是
B12: =ROW()-2 -> 10 | C12: 任职岗位名称 | E12: EHR系统 | F12: 年度 | G12: 是
A13: 工作量化数据 （看负荷） | B13: =ROW()-2 -> 11 | C13: 近2年牵头项目个数 | E13: ADPM | F13: 年度 | G13: 是
B14: =ROW()-2 -> 12 | C14: 近2年参与项目个数 | E14: 手工数据 | F14: 年度 | G14: 是
B15: =ROW()-2 -> 13 | C15: 负责的系统个数 | E15: ADPM | F15: 年度 | G15: 是
B16: =ROW()-2 -> 14 | C16: 是否参与过重大工程 | E16: 手工数据 | F16: 年度 | G16: 是
B17: =ROW()-2 -> 15 | C17: 近1年是否在党、工、团等组织中任职 | E17: 手工数据 | F17: 年度 | G17: 是
B18: =ROW()-2 -> 16 | C18: 党、工、团等组织中的任职职务 | E18: 手工数据 | F18: 年度 | G18: 是
B19: =ROW()-2 -> 17 | C19: 岗位变更次数 | E19: EHR系统 | F19: 年度 | G19: 是
A20: 特殊岗位/职责标识 （看角色） | B20: =ROW()-2 -> 18 | C20: 组长/骨干标识 | E20: 手工数据 | F20: 年度 | G20: 是
B21: =ROW()-2 -> 19 | C21: 产品经理标识 | E21: 手工数据 | F21: 年度 | G21: 是
B22: =ROW()-2 -> 20 | C22: 架构师标识 | E22: 手工数据 | F22: 年度 | G22: 是
A23: 学习与培养 （看潜力） | B23: =ROW()-2 -> 21 | C23: 近2年行外发表的论文、杂志的数量 | E23: 手工数据 | F23: 年度 | G23: 是
B24: =ROW()-2 -> 22 | C24: 近2年获得的部门级以上奖励、荣誉数量 | E24: 手工数据 | F24: 年度 | G24: 是
B25: =ROW()-2 -> 23 | C25: 近2年获得的部门级以上的最高荣誉名称 | E25: 手工数据 | F25: 年度 | G25: 是
B26: =ROW()-2 -> 24 | C26: 年度部门内分享/培训次数（作为培训者） | E26: 培训系统数据 | F26: 年度 | G26: 是
B27: =ROW()-2 -> 25 | C27: 年度部门外培训次数（作为培训者） | E27: 培训系统数据 | F27: 年度 | G27: 是
B28: =ROW()-2 -> 26 | C28: 年度部门外培训次数（作为被培训者） | E28: 培训系统数据 | F28: 年度 | G28: 是
B29: =ROW()-2 -> 27 | C29: 年度部门内分享/培训次数（作为被培训者） | E29: 培训系统数据 | F29: 年度 | G29: 是
B30: =ROW()-2 -> 28 | C30: 近2年带教的实习生数量 | E30: 综合台账登记 | F30: 年度 | G30: 是
B31: =ROW()-2 -> 29 | C31: 近2年带教的校招新行员的数量 | E31: 综合台账登记 | F31: 年度 | G31: 是
B32: =ROW()-2 -> 30 | C32: 近2年带教的实习生转正数量 | E32: 综合台账登记 | F32: 年度 | G32: 是
B33: =ROW()-2 -> 31 | C33: 近2年带教的校招新行员转正成绩为A的数量 | E33: EHR系统 | F33: 年度 | G33: 是
B34: =ROW()-2 -> 32 | C34: 近3个月查看知识库会议纪要次数 | E34: 智能知识库系统 | F34: 年度 | G34: 是
B35: =ROW()-2 -> 33 | C35: 当年资质证书获取情况 | E35: 台账登记 | F35: 年度 | G35: 是
A36: 硬实力 （看技能） | B36: =ROW()-2 -> 34 | C36: 数据分析师-数据分析工具运用能力 | E36: 技能考试/证书获取 | F36: 年度 | G36: 否 | H36: 技能考试
B37: =ROW()-2 -> 35 | C37: 数据分析师-算法模型开发能力 | E37: 技能考试/证书获取 | F37: 年度 | G37: 否 | H37: 技能考试
B38: =ROW()-2 -> 36 | C38: 数据分析师-营销运营能力 | E38: 技能考试/证书获取 | F38: 年度 | G38: 否 | H38: 技能考试
B39: =ROW()-2 -> 37 | C39: 数据研发师-SQL开发 | E39: 技能考试/证书获取 | F39: 年度 | G39: 否 | H39: 技能考试
B40: =ROW()-2 -> 38 | C40: 数据研发师-数据模型设计 | E40: 技能考试/证书获取 | F40: 年度 | G40: 否 | H40: 技能考试
...

Sheet 4 人员画像-月 季
A1: 月度主要监测：人员饱和度，员工异常行为数据，特殊事件分析（好坏两面）， 为部门资源调配提供数据支撑，对异常员工行为提前预警、提前干预，潜力员工挖掘。
A2: 类别 | B2: 序号 | C2: 指标名称 | D2: 数据来源 | E2: 更新频率 | F2: 目前数据是否已获取 | G2: 备注
A3: 基本信息 （看结构） | B3: =ROW()-2 -> 1 | C3: 年龄 | D3: EHR系统 | E3: - | F3: 是
B4: =ROW()-2 -> 2 | C4: 性别 | D4: EHR系统 | E4: - | F4: 是
B5: =ROW()-2 -> 3 | C5: 学历 | D5: EHR系统 | E5: - | F5: 是
B6: =ROW()-2 -> 4 | C6: 专业 | D6: EHR系统 | E6: - | F6: 是
B7: =ROW()-2 -> 5 | C7: 司龄 | D7: EHR系统 | E7: 年度 | F7: 是
B8: =ROW()-2 -> 6 | C8: 工龄 | D8: EHR系统 | E8: 年度 | F8: 是
B9: =ROW()-2 -> 7 | C9: 所在科室 | D9: EHR系统 | E9: 年度 | F9: 是
B10: =ROW()-2 -> 8 | C10: 所在组 | D10: EHR系统 | E10: 年度 | F10: 是
B11: =ROW()-2 -> 9 | C11: 校招/社招标识 | D11: EHR系统 | E11: 年度 | F11: 是
